Workbook
Name Alpha: Params!$B$4
Name Base: Params!$B$5
Name ConfMult: Params!$B$12
Name DivMult: Params!$B$11
Name HFA: Params!$B$6
Name KFloor: Params!$B$8
Name KMax: Params!$B$7
Name POMult_CC: Params!$B$15
Name POMult_DV: Params!$B$14
Name POMult_SB: Params!$B$16
Name POMult_WC: Params!$B$13
Name RestMajor: Params!$B$10
Name RestMinor: Params!$B$9

Sheet Instructions
A1: NFL Elo Template - one file per season
A3: This is a TEMPLATE. Never enter live data directly into this file - use File > Save As to make a copy
A4: named for the season (e.g. NFL_ELO_2024.xlsx), and enter that season's games into the copy.
A6: WHY ONE FILE PER SEASON
A7: Every formula only ever needs to see the games IN THIS FILE. There's no year-over-year buildup, so
A8: the file stays small and fast, and you always have one clean file per season to check against the
A9: Python database independently.
A11: STARTING A NEW SEASON (the Save As workflow)
A12: 1. Finish entering all of last season's games in last season's file. Check its Standings sheet.
A13: 2. Open THIS template (or last season's finished file - either works) and do File > Save As, naming
A14: it for the new season.
A15: 3. On the new file's Teams sheet, column G (PreseasonRating): for each team, paste the VALUE (not
... A57: - Deduping re-entered games - Excel won't stop you from typing the same game twice.

Sheet Params
A1: Elo engine parameters
A2: Matches engine.py's BASELINE_PARAMS exactly. Same for every season - carries over automatically when you Save As.
A3: Name | B3: Value | C3: Meaning
A4: Alpha | B4: 0.3 | C4: Season-to-season carry-over weight
A5: Base | B5: 1500 | C5: League-average / expansion-team rating
A6: HFA | B6: 72 | C6: Home field advantage, in Elo points
A7: KMax | B7: 46 | C7: K at the start of a team's season
A8: KFloor | B8: 36.2 | C8: K decays to this by the last game of the regular season
A9: RestMinor | B9: 6 | C9: Adjustment for a 1-4 day rest differential (short week)
A10: RestMajor | B10: 24 | C10: Adjustment for a 6+ day rest differential (bye week+)
A11: DivMult | B11: 1.1 | C11: Multiplier for divisional games
A12: ConfMult | B12: 1.02 | C12: Multiplier for conference (non-division) games
A13: POMult_WC | B13: 1.1 | C13: Playoff round multiplier - Wild Card
A14: POMult_DV | B14: 1.2 | C14: Playoff round multiplier - Divisional
A15: POMult_CC | B15: 1.35 | C15: Playoff round multiplier - Conference Championship
A16: POMult_SB | B16: 1.5 | C16: Playoff round multiplier - Super Bowl
A18: Regular-season length rule (built into the Games table): 17 games if Season>=2021, else 16.

Sheet Teams
A1: Team reference
A2: PreseasonRating (col G) is this team's Elo going into THIS season.
A3: First season ever for the league: leave every PreseasonRating at Base (1500).
A4: Every later season: open last season's finished file, copy each team's Rating from its Standings
A5: sheet, and paste the VALUES (not formulas) into the matching row here before entering this season's games.
A7: TeamID | B7: TeamName | C7: Conf | D7: Div | E7: Pre02Conf | F7: Pre02Div | G7: PreseasonRating
A8: ARI | B8: Arizona Cardinals | C8: NFC | D8: West | E8: NFC | F8: East | G8: 1500
A9: ATL | B9: Atlanta Falcons | C9: NFC | D9: South | E9: NFC | F9: West | G9: 1500
A10: BAL | B10: Baltimore Ravens | C10: AFC | D10: North | E10: AFC | F10: Central | G10: 1500
A11: BUF | B11: Buffalo Bills | C11: AFC | D11: East | E11: AFC | F11: East | G11: 1500
A12: CAR | B12: Carolina Panthers | C12: NFC | D12: South | E12: NFC | F12: West | G12: 1500
A13: CHI | B13: Chicago Bears | C13: NFC | D13: North | E13: NFC | F13: Central | G13: 1500
A14: CIN | B14: Cincinnati Bengals | C14: AFC | D14: North | E14: AFC | F14: Central | G14: 1500
A15: DAL | B15: Dallas Cowboys | C15: NFC | D15: East | E15: NFC | F15: East | G15: 1500
A16: DEN | B16: Denver Broncos | C16: AFC | D16: West | E16: AFC | F16: West | G16: 1500
A17: DET | B17: Detroit Lions | C17: NFC | D17: North | E17: NFC | F17: Central | G17: 1500
A18: GB | B18: Green Bay Packers | C18: NFC | D18: North | E18: NFC | F18: Central | G18: 1500
A19: TEN | B19: Houston Oilers | C19: AFC | D19: South | E19: AFC | F19: Central | G19: 1500
... A37: WAS | B37: Washington Redskins | C37: NFC | D37: East | E37: NFC | F37: East | G37: 1500

Sheet Games
A1: Date | B1: Season | C1: Type | D1: Round | E1: Team | F1: Opponent | G1: HomeAway | H1: PointsFor | I1: PointsAgainst | J1: OT | K1: Conf | L1: OppConf | M1: Div | N1: OppDiv | O1: ConfG | P1: DivG | Q1: SeasonStart | R1: Week | S1: GamesPlayed | T1: PrevWeekTeam | U1: PrevWeekOpp | V1: DaysOff | W1: OppDaysOff | X1: RestAdj | Y1: PreGmRate | Z1: OppPreGmRate | AA1: ExpectedWin | AB1: MOV | AC1: Result | AD1: Accuracy | AE1: Test | AF1: SeasonLen | AG1: K | AH1: MOVMult | AI1: POMult | AJ1: Keff | AK1: RatingChange | AL1: PostGmRate | AM1: W | AN1: L | AO1: T
A2: 35309 | B2: 1996 | C2: R | D2: RS | E2: CAR | F2: ATL | G2: H | H2: 29 | I2: 6 | J2: 0 | K2: =IF(Games[[#This Row],[Team]]="","",IF(Games[[#This Row],[Season]]>2001,IFERROR(INDEX(Teams[Conf],MATCH(Games[[#This Row],[Team]],Teams[TeamID],0)),"NEW"),IFERROR(INDEX(Teams[Pre02Conf],MATCH(Games[[#This Row],[Team]],Teams[TeamID],0)),"NEW"))) -> NFC | L2: =IF(Games[[#This Row],[Team]]="","",IF(Games[[#This Row],[Season]]>2001,IFERROR(INDEX(Teams[Conf],MATCH(Games[[#This Row],[Opponent]],Teams[TeamID],0)),"NEW"),IFERROR(INDEX(Teams[Pre02Conf],MATCH(Games[[#This Row],[Opponent]],Teams[TeamID],0)),"NEW"))) -> NFC | M2: =IF(Games[[#This Row],[Team]]="","",IF(Games[[#This Row],[Season]]>2001,IFERROR(INDEX(Teams[Div],MATCH(Games[[#This Row],[Team]],Teams[TeamID],0)),"NEW"),IFERROR(INDEX(Teams[Pre02Div],MATCH(Games[[#This Row],[Team]],Teams[TeamID],0)),"NEW"))) -> West | N2: =IF(Games[[#This Row],[Team]]="","",IF(Games[[#This Row],[Season]]>2001,IFERROR(INDEX(Teams[Div],MATCH(Games[[#This Row],[Opponent]],Teams[TeamID],0)),"NEW"),IFERROR(INDEX(Teams[Pre02Div],MATCH(Games[[#This Row],[Opponent]],Teams[TeamID],0)),"NEW"))) -> West | O2: =IF(Games[[#This Row],[Team]]="","",IF(Games[[#This Row],[Conf]]=Games[[#This Row],[OppConf]],1,0)) -> 1 | P2: =IF(Games[[#This Row],[Team]]="","",IF(AND(Games[[#This Row],[Conf]]=Games[[#This Row],[OppConf]],Games[[#This Row],[Div]]=Games[[#This Row],[OppDiv]]),1,0)) -> 1 | Q2: =IF(Games[[#This Row],[Team]]="","",_xlfn.MINIFS(Games[Date],Games[Season],Games[[#This Row],[Season]])) -> 35309 | R2: =IF(Games[[#This Row],[Team]]="","",INT((Games[[#This Row],[Date]]-(Games[[#This Row],[SeasonStart]]-MOD(WEEKDAY(Games[[#This Row],[SeasonStart]],2)-2,7)))/7)+1) -> 1 | S2: =IF(Games[[#This Row],[Team]]="","",COUNTIFS(Games[Team],Games[[#This Row],[Team]],Games[Season],Games[[#This Row],[Season]],Games[Week],"<="&Games[[#This Row],[Week]])) -> 1 | T2: =IF(Games[[#This Row],[Team]]="","",_xlfn.MAXIFS(Games[Week],Games[Team],Games[[#This Row],[Team]],Games[Season],Games[[#This Row],[Season]],Games[Week],"<"&Games[[#This Row],[Week]])) -> 0 | U2: =IF(Games[[#This Row],[Team]]="","",_xlfn.MAXIFS(Games[Week],Games[Team],Games[[#This Row],[Opponent]],Games[Season],Games[[#This Row],[Season]],Games[Week],"<"&Games[[#This Row],[Week]])) -> 0 | V2: =IF(Games[[#This Row],[Team]]="","",IF(Games[[#This Row],[PrevWeekTeam]]=0,"",Games[[#This Row],[Date]]-SUMIFS(Games[Date],Games[Team],Games[[#This Row],[Team]],Games[Season],Games[[#This Row],[Season]],Games[Week],Games[[#This Row],[PrevWeekTeam]]))) | W2: =IF(Games[[#This Row],[Team]]="","",IF(Games[[#This Row],[PrevWeekOpp]]=0,"",Games[[#This Row],[Date]]-SUMIFS(Games[Date],Games[Team],Games[[#This Row],[Opponent]],Games[Season],Games[[#This Row],[Season]],Games[Week],Games[[#This Row],[PrevWeekOpp]]))) | X2: =IF(Games[[#This Row],[Team]]="","",IF(OR(Games[[#This Row],[DaysOff]]="",Games[[#This Row],[OppDaysOff]]=""),0,IF(Games[[#This Row],[DaysOff]]-Games[[#This Row],[OppDaysOff]]=0,0,IF(ABS(Games[[#This Row],[DaysOff]]-Games[[#This Row],[OppDaysOff]])>=6,IF(Games[[#This Row],[DaysOff]]-Games[[#This Row],[OppDaysOff]]>0,RestMajor,-RestMajor),IF(Games[[#This Row],[DaysOff]]-Games[[#This Row],[OppDaysOff]]>0,RestMinor,-RestMinor))))) -> 0 | Y2: =IF(Games[[#This Row],[Team]]="","",IF(Games[[#This Row],[PrevWeekTeam]]>0,SUMIFS(Games[PostGmRate],Games[Team],Games[[#This Row],[Team]],Games[Season],Games[[#This Row],[Season]],Games[Week],Games[[#This Row],[PrevWeekTeam]]),Alpha*IFERROR(INDEX(Teams[PreseasonRating],MATCH(Games[[#This Row],[Team]],Teams[TeamID],0)),Base)+(1-Alpha)*Base)) -> 1500 | Z2: =IF(Games[[#This Row],[Team]]="","",IF(Games[[#This Row],[PrevWeekOpp]]>0,SUMIFS(Games[PostGmRate],Games[Team],Games[[#This Row],[Opponent]],Games[Season],Games[[#This Row],[Season]],Games[Week],Games[[#This Row],[PrevWeekOpp]]),Alpha*IFERROR(INDEX(Teams[PreseasonRating],MATCH(Games[[#This Row],[Opponent]],Teams[TeamID],0)),Base)+(1-Alpha)*Base)) -> 1500 | AA2: =IF(Games[[#This Row],[Team]]="","",1/(1+10^(((Games[[#This Row],[OppPreGmRate]]+IF(Games[[#This Row],[HomeAway]]="A",HFA-Games[[#This Row],[RestAdj]],0))-(Games[[#This Row],[PreGmRate]]+IF(Games[[#This Row],[HomeAway]]="H",HFA+Games[[#This Row],[RestAdj]],0)))/400))) -> 0.60215809 | AB2: =IF(Games[[#This Row],[Team]]="","",Games[[#This Row],[PointsFor]]-Games[[#This Row],[PointsAgainst]]) -> 23 | AC2: =IF(Games[[#This Row],[Team]]="","",IF(Games[[#This Row],[MOV]]>0,1,IF(Games[[#This Row],[MOV]]=0,0.5,0))) -> 1 | AD2: =IF(Games[[#This Row],[Team]]="","",--(OR(AND(Games[[#This Row],[ExpectedWin]]>=0.5,Games[[#This Row],[Result]]=1),AND(Games[[#This Row],[ExpectedWin]]<0.5,Games[[#This Row],[Result]]=0)))) -> 1 | AE2: =IF(Games[[#This Row],[Team]]="","",-(Games[[#This Row],[Result]]*LN(Games[[#This Row],[ExpectedWin]])+(1-Games[[#This Row],[Result]])*LN(1-Games[[#This Row],[ExpectedWin]]))) -> 0.50723525 | AF2: =IF(Games[[#This Row],[Team]]="","",IF(Games[[#This Row],[Season]]>=2021,17,16)) -> 16 | AG2: =IF(Games[[#This Row],[Team]]="","",KMax-(KMax-KFloor)*MIN(Games[[#This Row],[GamesPlayed]],Games[[#This Row],[SeasonLen]])/Games[[#This Row],[SeasonLen]]) -> 45.3875 | AH2: =IF(Games[[#This Row],[Team]]="","",((ABS(Games[[#This Row],[MOV]])+3)^0.8)/(7.5+0.006*ABS(Games[[#This Row],[PreGmRate]]-Games[[#This Row],[OppPreGmRate]]))*IF(Games[[#This Row],[OT]]=1,0.7,1)) -> 1.8068305 | AI2: =IF(Games[[#This Row],[Team]]="","",IF(Games[[#This Row],[Type]]="P",_xlfn.IFS(Games[[#This Row],[Round]]="WC",POMult_WC,Games[[#This Row],[Round]]="DV",POMult_DV,Games[[#This Row],[Round]]="CC",POMult_CC,Games[[#This Row],[Round]]="SB",POMult_SB,TRUE,1),1)) -> 1 | AJ2: =IF(Games[[#This Row],[Team]]="","",Games[[#This Row],[K]]*IF(Games[[#This Row],[DivG]]=1,DivMult,1)*IF(Games[[#This Row],[ConfG]]=1,ConfMult,1)*Games[[#This Row],[POMult]]) -> 50.924775 | AK2: =IF(Games[[#This Row],[Team]]="","",(Games[[#This Row],[Keff]]*Games[[#This Row],[MOVMult]])*(Games[[#This Row],[Result]]-Games[[#This Row],[ExpectedWin]])) -> 36.606403 | AL2: =IF(Games[[#This Row],[Team]]="","",Games[[#This Row],[PreGmRate]]+Games[[#This Row],[RatingChange]]) -> 1536.6064 | AM2: =IF(Games[[#This Row],[Team]]="","",IF(Games[[#This Row],[Type]]="R",IF(Games[[#This Row],[Result]]>0.5,1,0),0)) -> 1 | AN2: =IF(Games[[#This Row],[Team]]="","",IF(Games[[#This Row],[Type]]="R",IF(Games[[#This Row],[Result]]<0.5,1,0),0)) -> 0 | AO2: =IF(Games[[#This Row],[Team]]="","",IF(Games[[#This Row],[Type]]="R",IF(Games[[#This Row],[Result]]=0.5,1,0),0)) -> 0
A3: 35309 | B3: 1996 | C3: R | D3: RS | E3: ATL | F3: CAR | G3: A | H3: 6 | I3: 29 | J3: 0 | K3: =IF(Games[[#This Row],[Team]]="","",IF(Games[[#This Row],[Season]]>2001,IFERROR(INDEX(Teams[Conf],MATCH(Games[[#This Row],[Team]],Teams[TeamID],0)),"NEW"),IFERROR(INDEX(Teams[Pre02Conf],MATCH(Games[[#This Row],[Team]],Teams[TeamID],0)),"NEW"))) -> NFC | L3: =IF(Games[[#This Row],[Team]]="","",IF(Games[[#This Row],[Season]]>2001,IFERROR(INDEX(Teams[Conf],MATCH(Games[[#This Row],[Opponent]],Teams[TeamID],0)),"NEW"),IFERROR(INDEX(Teams[Pre02Conf],MATCH(Games[[#This Row],[Opponent]],Teams[TeamID],0)),"NEW"))) -> NFC | M3: =IF(Games[[#This Row],[Team]]="","",IF(Games[[#This Row],[Season]]>2001,IFERROR(INDEX(Teams[Div],MATCH(Games[[#This Row],[Team]],Teams[TeamID],0)),"NEW"),IFERROR(INDEX(Teams[Pre02Div],MATCH(Games[[#This Row],[Team]],Teams[TeamID],0)),"NEW"))) -> West | N3: =IF(Games[[#This Row],[Team]]="","",IF(Games[[#This Row],[Season]]>2001,IFERROR(INDEX(Teams[Div],MATCH(Games[[#This Row],[Opponent]],Teams[TeamID],0)),"NEW"),IFERROR(INDEX(Teams[Pre02Div],MATCH(Games[[#This Row],[Opponent]],Teams[TeamID],0)),"NEW"))) -> West | O3: =IF(Games[[#This Row],[Team]]="","",IF(Games[[#This Row],[Conf]]=Games[[#This Row],[OppConf]],1,0)) -> 1 | P3: =IF(Games[[#This Row],[Team]]="","",IF(AND(Games[[#This Row],[Conf]]=Games[[#This Row],[OppConf]],Games[[#This Row],[Div]]=Games[[#This Row],[OppDiv]]),1,0)) -> 1 | Q3: =IF(Games[[#This Row],[Team]]="","",_xlfn.MINIFS(Games[Date],Games[Season],Games[[#This Row],[Season]])) -> 35309 | R3: =IF(Games[[#This Row],[Team]]="","",INT((Games[[#This Row],[Date]]-(Games[[#This Row],[SeasonStart]]-MOD(WEEKDAY(Games[[#This Row],[SeasonStart]],2)-2,7)))/7)+1) -> 1 | S3: =IF(Games[[#This Row],[Team]]="","",COUNTIFS(Games[Team],Games[[#This Row],[Team]],Games[Season],Games[[#This Row],[Season]],Games[Week],"<="&Games[[#This Row],[Week]])) -> 1 | T3: =IF(Games[[#This Row],[Team]]="","",_xlfn.MAXIFS(Games[Week],Games[Team],Games[[#This Row],[Team]],Games[Season],Games[[#This Row],[Season]],Games[Week],"<"&Games[[#This Row],[Week]])) -> 0 | U3: =IF(Games[[#This Row],[Team]]="","",_xlfn.MAXIFS(Games[Week],Games[Team],Games[[#This Row],[Opponent]],Games[Season],Games[[#This Row],[Season]],Games[Week],"<"&Games[[#This Row],[Week]])) -> 0 | V3: =IF(Games[[#This Row],[Team]]="","",IF(Games[[#This Row],[PrevWeekTeam]]=0,"",Games[[#This Row],[Date]]-SUMIFS(Games[Date],Games[Team],Games[[#This Row],[Team]],Games[Season],Games[[#This Row],[Season]],Games[Week],Games[[#This Row],[PrevWeekTeam]]))) | W3: =IF(Games[[#This Row],[Team]]="","",IF(Games[[#This Row],[PrevWeekOpp]]=0,"",Games[[#This Row],[Date]]-SUMIFS(Games[Date],Games[Team],Games[[#This Row],[Opponent]],Games[Season],Games[[#This Row],[Season]],Games[Week],Games[[#This Row],[PrevWeekOpp]]))) | X3: =IF(Games[[#This Row],[Team]]="","",IF(OR(Games[[#This Row],[DaysOff]]="",Games[[#This Row],[OppDaysOff]]=""),0,IF(Games[[#This Row],[DaysOff]]-Games[[#This Row],[OppDaysOff]]=0,0,IF(ABS(Games[[#This Row],[DaysOff]]-Games[[#This Row],[OppDaysOff]])>=6,IF(Games[[#This Row],[DaysOff]]-Games[[#This Row],[OppDaysOff]]>0,RestMajor,-RestMajor),IF(Games[[#This Row],[DaysOff]]-Games[[#This Row],[OppDaysOff]]>0,RestMinor,-RestMinor))))) -> 0 | Y3: =IF(Games[[#This Row],[Team]]="","",IF(Games[[#This Row],[PrevWeekTeam]]>0,SUMIFS(Games[PostGmRate],Games[Team],Games[[#This Row],[Team]],Games[Season],Games[[#This Row],[Season]],Games[Week],Games[[#This Row],[PrevWeekTeam]]),Alpha*IFERROR(INDEX(Teams[PreseasonRating],MATCH(Games[[#This Row],[Team]],Teams[TeamID],0)),Base)+(1-Alpha)*Base)) -> 1500 | Z3: =IF(Games[[#This Row],[Team]]="","",IF(Games[[#This Row],[PrevWeekOpp]]>0,SUMIFS(Games[PostGmRate],Games[Team],Games[[#This Row],[Opponent]],Games[Season],Games[[#This Row],[Season]],Games[Week],Games[[#This Row],[PrevWeekOpp]]),Alpha*IFERROR(INDEX(Teams[PreseasonRating],MATCH(Games[[#This Row],[Opponent]],Teams[TeamID],0)),Base)+(1-Alpha)*Base)) -> 1500 | AA3: =IF(Games[[#This Row],[Team]]="","",1/(1+10^(((Games[[#This Row],[OppPreGmRate]]+IF(Games[[#This Row],[HomeAway]]="A",HFA-Games[[#This Row],[RestAdj]],0))-(Games[[#This Row],[PreGmRate]]+IF(Games[[#This Row],[HomeAway]]="H",HFA+Games[[#This Row],[RestAdj]],0)))/400))) -> 0.39784191 | AB3: =IF(Games[[#This Row],[Team]]="","",Games[[#This Row],[PointsFor]]-Games[[#This Row],[PointsAgainst]]) -> -23 | AC3: =IF(Games[[#This Row],[Team]]="","",IF(Games[[#This Row],[MOV]]>0,1,IF(Games[[#This Row],[MOV]]=0,0.5,0))) -> 0 | AD3: =IF(Games[[#This Row],[Team]]="","",--(OR(AND(Games[[#This Row],[ExpectedWin]]>=0.5,Games[[#This Row],[Result]]=1),AND(Games[[#This Row],[ExpectedWin]]<0.5,Games[[#This Row],[Result]]=0)))) -> 1 | AE3: =IF(Games[[#This Row],[Team]]="","",-(Games[[#This Row],[Result]]*LN(Games[[#This Row],[ExpectedWin]])+(1-Games[[#This Row],[Result]])*LN(1-Games[[#This Row],[ExpectedWin]]))) -> 0.50723525 | AF3: =IF(Games[[#This Row],[Team]]="","",IF(Games[[#This Row],[Season]]>=2021,17,16)) -> 16 | AG3: =IF(Games[[#This Row],[Team]]="","",KMax-(KMax-KFloor)*MIN(Games[[#This Row],[GamesPlayed]],Games[[#This Row],[SeasonLen]])/Games[[#This Row],[SeasonLen]]) -> 45.3875 | AH3: =IF(Games[[#This Row],[Team]]="","",((ABS(Games[[#This Row],[MOV]])+3)^0.8)/(7.5+0.006*ABS(Games[[#This Row],[PreGmRate]]-Games[[#This Row],[OppPreGmRate]]))*IF(Games[[#This Row],[OT]]=1,0.7,1)) -> 1.8068305 | AI3: =IF(Games[[#This Row],[Team]]="","",IF(Games[[#This Row],[Type]]="P",_xlfn.IFS(Games[[#This Row],[Round]]="WC",POMult_WC,Games[[#This Row],[Round]]="DV",POMult_DV,Games[[#This Row],[Round]]="CC",POMult_CC,Games[[#This Row],[Round]]="SB",POMult_SB,TRUE,1),1)) -> 1 | AJ3: =IF(Games[[#This Row],[Team]]="","",Games[[#This Row],[K]]*IF(Games[[#This Row],[DivG]]=1,DivMult,1)*IF(Games[[#This Row],[ConfG]]=1,ConfMult,1)*Games[[#This Row],[POMult]]) -> 50.924775 | AK3: =IF(Games[[#This Row],[Team]]="","",(Games[[#This Row],[Keff]]*Games[[#This Row],[MOVMult]])*(Games[[#This Row],[Result]]-Games[[#This Row],[ExpectedWin]])) -> -36.606403 | AL3: =IF(Games[[#This Row],[Team]]="","",Games[[#This Row],[PreGmRate]]+Games[[#This Row],[RatingChange]]) -> 1463.3936 | AM3: =IF(Games[[#This Row],[Team]]="","",IF(Games[[#This Row],[Type]]="R",IF(Games[[#This Row],[Result]]>0.5,1,0),0)) -> 0 | AN3: =IF(Games[[#This Row],[Team]]="","",IF(Games[[#This Row],[Type]]="R",IF(Games[[#This Row],[Result]]<0.5,1,0),0)) -> 1 | AO3: =IF(Games[[#This Row],[Team]]="","",IF(Games[[#This Row],[Type]]="R",IF(Games[[#This Row],[Result]]=0.5,1,0),0)) -> 0
A4: 35309 | B4: 1996 | C4: R | D4: RS | E4: STL | F4: CIN | G4: H | H4: 26 | I4: 16 | J4: 0 | K4: =IF(Games[[#This Row],[Team]]="","",IF(Games[[#This Row],[Season]]>2001,IFERROR(INDEX(Teams[Conf],MATCH(Games[[#This Row],[Team]],Teams[TeamID],0)),"NEW"),IFERROR(INDEX(Teams[Pre02Conf],MATCH(Games[[#This Row],[Team]],Teams[TeamID],0)),"NEW"))) -> NFC | L4: =IF(Games[[#This Row],[Team]]="","",IF(Games[[#This Row],[Season]]>2001,IFERROR(INDEX(Teams[Conf],MATCH(Games[[#This Row],[Opponent]],Teams[TeamID],0)),"NEW"),IFERROR(INDEX(Teams[Pre02Conf],MATCH(Games[[#This Row],[Opponent]],Teams[TeamID],0)),"NEW"))) -> AFC | M4: =IF(Games[[#This Row],[Team]]="","",IF(Games[[#This Row],[Season]]>2001,IFERROR(INDEX(Teams[Div],MATCH(Games[[#This Row],[Team]],Teams[TeamID],0)),"NEW"),IFERROR(INDEX(Teams[Pre02Div],MATCH(Games[[#This Row],[Team]],Teams[TeamID],0)),"NEW"))) -> West | N4: =IF(Games[[#This Row],[Team]]="","",IF(Games[[#This Row],[Season]]>2001,IFERROR(INDEX(Teams[Div],MATCH(Games[[#This Row],[Opponent]],Teams[TeamID],0)),"NEW"),IFERROR(INDEX(Teams[Pre02Div],MATCH(Games[[#This Row],[Opponent]],Teams[TeamID],0)),"NEW"))) -> Central | O4: =IF(Games[[#This Row],[Team]]="","",IF(Games[[#This Row],[Conf]]=Games[[#This Row],[OppConf]],1,0)) -> 0 | P4: =IF(Games[[#This Row],[Team]]="","",IF(AND(Games[[#This Row],[Conf]]=Games[[#This Row],[OppConf]],Games[[#This Row],[Div]]=Games[[#This Row],[OppDiv]]),1,0)) -> 0 | Q4: =IF(Games[[#This Row],[Team]]="","",_xlfn.MINIFS(Games[Date],Games[Season],Games[[#This Row],[Season]])) -> 35309 | R4: =IF(Games[[#This Row],[Team]]="","",INT((Games[[#This Row],[Date]]-(Games[[#This Row],[SeasonStart]]-MOD(WEEKDAY(Games[[#This Row],[SeasonStart]],2)-2,7)))/7)+1) -> 1 | S4: =IF(Games[[#This Row],[Team]]="","",COUNTIFS(Games[Team],Games[[#This Row],[Team]],Games[Season],Games[[#This Row],[Season]],Games[Week],"<="&Games[[#This Row],[Week]])) -> 1 | T4: =IF(Games[[#This Row],[Team]]="","",_xlfn.MAXIFS(Games[Week],Games[Team],Games[[#This Row],[Team]],Games[Season],Games[[#This Row],[Season]],Games[Week],"<"&Games[[#This Row],[Week]])) -> 0 | U4: =IF(Games[[#This Row],[Team]]="","",_xlfn.MAXIFS(Games[Week],Games[Team],Games[[#This Row],[Opponent]],Games[Season],Games[[#This Row],[Season]],Games[Week],"<"&Games[[#This Row],[Week]])) -> 0 | V4: =IF(Games[[#This Row],[Team]]="","",IF(Games[[#This Row],[PrevWeekTeam]]=0,"",Games[[#This Row],[Date]]-SUMIFS(Games[Date],Games[Team],Games[[#This Row],[Team]],Games[Season],Games[[#This Row],[Season]],Games[Week],Games[[#This Row],[PrevWeekTeam]]))) | W4: =IF(Games[[#This Row],[Team]]="","",IF(Games[[#This Row],[PrevWeekOpp]]=0,"",Games[[#This Row],[Date]]-SUMIFS(Games[Date],Games[Team],Games[[#This Row],[Opponent]],Games[Season],Games[[#This Row],[Season]],Games[Week],Games[[#This Row],[PrevWeekOpp]]))) | X4: =IF(Games[[#This Row],[Team]]="","",IF(OR(Games[[#This Row],[DaysOff]]="",Games[[#This Row],[OppDaysOff]]=""),0,IF(Games[[#This Row],[DaysOff]]-Games[[#This Row],[OppDaysOff]]=0,0,IF(ABS(Games[[#This Row],[DaysOff]]-Games[[#This Row],[OppDaysOff]])>=6,IF(Games[[#This Row],[DaysOff]]-Games[[#This Row],[OppDaysOff]]>0,RestMajor,-RestMajor),IF(Games[[#This Row],[DaysOff]]-Games[[#This Row],[OppDaysOff]]>0,RestMinor,-RestMinor))))) -> 0 | Y4: =IF(Games[[#This Row],[Team]]="","",IF(Games[[#This Row],[PrevWeekTeam]]>0,SUMIFS(Games[PostGmRate],Games[Team],Games[[#This Row],[Team]],Games[Season],Games[[#This Row],[Season]],Games[Week],Games[[#This Row],[PrevWeekTeam]]),Alpha*IFERROR(INDEX(Teams[PreseasonRating],MATCH(Games[[#This Row],[Team]],Teams[TeamID],0)),Base)+(1-Alpha)*Base)) -> 1500 | Z4: =IF(Games[[#This Row],[Team]]="","",IF(Games[[#This Row],[PrevWeekOpp]]>0,SUMIFS(Games[PostGmRate],Games[Team],Games[[#This Row],[Opponent]],Games[Season],Games[[#This Row],[Season]],Games[Week],Games[[#This Row],[PrevWeekOpp]]),Alpha*IFERROR(INDEX(Teams[PreseasonRating],MATCH(Games[[#This Row],[Opponent]],Teams[TeamID],0)),Base)+(1-Alpha)*Base)) -> 1500 | AA4: =IF(Games[[#This Row],[Team]]="","",1/(1+10^(((Games[[#This Row],[OppPreGmRate]]+IF(Games[[#This Row],[HomeAway]]="A",HFA-Games[[#This Row],[RestAdj]],0))-(Games[[#This Row],[PreGmRate]]+IF(Games[[#This Row],[HomeAway]]="H",HFA+Games[[#This Row],[RestAdj]],0)))/400))) -> 0.60215809 | AB4: =IF(Games[[#This Row],[Team]]="","",Games[[#This Row],[PointsFor]]-Games[[#This Row],[PointsAgainst]]) -> 10 | AC4: =IF(Games[[#This Row],[Team]]="","",IF(Games[[#This Row],[MOV]]>0,1,IF(Games[[#This Row],[MOV]]=0,0.5,0))) -> 1 | AD4: =IF(Games[[#This Row],[Team]]="","",--(OR(AND(Games[[#This Row],[ExpectedWin]]>=0.5,Games[[#This Row],[Result]]=1),AND(Games[[#This Row],[ExpectedWin]]<0.5,Games[[#This Row],[Result]]=0)))) -> 1 | AE4: =IF(Games[[#This Row],[Team]]="","",-(Games[[#This Row],[Result]]*LN(Games[[#This Row],[ExpectedWin]])+(1-Games[[#This Row],[Result]])*LN(1-Games[[#This Row],[ExpectedWin]]))) -> 0.50723525 | AF4: =IF(Games[[#This Row],[Team]]="","",IF(Games[[#This Row],[Season]]>=2021,17,16)) -> 16 | AG4: =IF(Games[[#This Row],[Team]]="","",KMax-(KMax-KFloor)*MIN(Games[[#This Row],[GamesPlayed]],Games[[#This Row],[SeasonLen]])/Games[[#This Row],[SeasonLen]]) -> 45.3875 | AH4: =IF(Games[[#This Row],[Team]]="","",((ABS(Games[[#This Row],[MOV]])+3)^0.8)/(7.5+0.006*ABS(Games[[#This Row],[PreGmRate]]-Games[[#This Row],[OppPreGmRate]]))*IF(Games[[#This Row],[OT]]=1,0.7,1)) -> 1.0377516 | AI4: =IF(Games[[#This Row],[Team]]="","",IF(Games[[#This Row],[Type]]="P",_xlfn.IFS(Games[[#This Row],[Round]]="WC",POMult_WC,Games[[#This Row],[Round]]="DV",POMult_DV,Games[[#This Row],[Round]]="CC",POMult_CC,Games[[#This Row],[Round]]="SB",POMult_SB,TRUE,1),1)) -> 1 | AJ4: =IF(Games[[#This Row],[Team]]="","",Games[[#This Row],[K]]*IF(Games[[#This Row],[DivG]]=1,DivMult,1)*IF(Games[[#This Row],[ConfG]]=1,ConfMult,1)*Games[[#This Row],[POMult]]) -> 45.3875 | AK4: =IF(Games[[#This Row],[Team]]="","",(Games[[#This Row],[Keff]]*Games[[#This Row],[MOVMult]])*(Games[[#This Row],[Result]]-Games[[#This Row],[ExpectedWin]])) -> 18.738732 | AL4: =IF(Games[[#This Row],[Team]]="","",Games[[#This Row],[PreGmRate]]+Games[[#This Row],[RatingChange]]) -> 1518.7387 | AM4: =IF(Games[[#This Row],[Team]]="","",IF(Games[[#This Row],[Type]]="R",IF(Games[[#This Row],[Result]]>0.5,1,0),0)) -> 1 | AN4: =IF(Games[[#This Row],[Team]]="","",IF(Games[[#This Row],[Type]]="R",IF(Games[[#This Row],[Result]]<0.5,1,0),0)) -> 0 | AO4: =IF(Games[[#This Row],[Team]]="","",IF(Games[[#This Row],[Type]]="R",IF(Games[[#This Row],[Result]]=0.5,1,0),0)) -> 0
A5: 35309 | B5: 1996 | C5: R | D5: RS | E5: CIN | F5: STL | G5: A | H5: 16 | I5: 26 | J5: 0 | K5: =IF(Games[[#This Row],[Team]]="","",IF(Games[[#This Row],[Season]]>2001,IFERROR(INDEX(Teams[Conf],MATCH(Games[[#This Row],[Team]],Teams[TeamID],0)),"NEW"),IFERROR(INDEX(Teams[Pre02Conf],MATCH(Games[[#This Row],[Team]],Teams[TeamID],0)),"NEW"))) -> AFC | L5: =IF(Games[[#This Row],[Team]]="","",IF(Games[[#This Row],[Season]]>2001,IFERROR(INDEX(Teams[Conf],MATCH(Games[[#This Row],[Opponent]],Teams[TeamID],0)),"NEW"),IFERROR(INDEX(Teams[Pre02Conf],MATCH(Games[[#This Row],[Opponent]],Teams[TeamID],0)),"NEW"))) -> NFC | M5: =IF(Games[[#This Row],[Team]]="","",IF(Games[[#This Row],[Season]]>2001,IFERROR(INDEX(Teams[Div],MATCH(Games[[#This Row],[Team]],Teams[TeamID],0)),"NEW"),IFERROR(INDEX(Teams[Pre02Div],MATCH(Games[[#This Row],[Team]],Teams[TeamID],0)),"NEW"))) -> Central | N5: =IF(Games[[#This Row],[Team]]="","",IF(Games[[#This Row],[Season]]>2001,IFERROR(INDEX(Teams[Div],MATCH(Games[[#This Row],[Opponent]],Teams[TeamID],0)),"NEW"),IFERROR(INDEX(Teams[Pre02Div],MATCH(Games[[#This Row],[Opponent]],Teams[TeamID],0)),"NEW"))) -> West | O5: =IF(Games[[#This Row],[Team]]="","",IF(Games[[#This Row],[Conf]]=Games[[#This Row],[OppConf]],1,0)) -> 0 | P5: =IF(Games[[#This Row],[Team]]="","",IF(AND(Games[[#This Row],[Conf]]=Games[[#This Row],[OppConf]],Games[[#This Row],[Div]]=Games[[#This Row],[OppDiv]]),1,0)) -> 0 | Q5: =IF(Games[[#This Row],[Team]]="","",_xlfn.MINIFS(Games[Date],Games[Season],Games[[#This Row],[Season]])) -> 35309 | R5: =IF(Games[[#This Row],[Team]]="","",INT((Games[[#This Row],[Date]]-(Games[[#This Row],[SeasonStart]]-MOD(WEEKDAY(Games[[#This Row],[SeasonStart]],2)-2,7)))/7)+1) -> 1 | S5: =IF(Games[[#This Row],[Team]]="","",COUNTIFS(Games[Team],Games[[#This Row],[Team]],Games[Season],Games[[#This Row],[Season]],Games[Week],"<="&Games[[#This Row],[Week]])) -> 1 | T5: =IF(Games[[#This Row],[Team]]="","",_xlfn.MAXIFS(Games[Week],Games[Team],Games[[#This Row],[Team]],Games[Season],Games[[#This Row],[Season]],Games[Week],"<"&Games[[#This Row],[Week]])) -> 0 | U5: =IF(Games[[#This Row],[Team]]="","",_xlfn.MAXIFS(Games[Week],Games[Team],Games[[#This Row],[Opponent]],Games[Season],Games[[#This Row],[Season]],Games[Week],"<"&Games[[#This Row],[Week]])) -> 0 | V5: =IF(Games[[#This Row],[Team]]="","",IF(Games[[#This Row],[PrevWeekTeam]]=0,"",Games[[#This Row],[Date]]-SUMIFS(Games[Date],Games[Team],Games[[#This Row],[Team]],Games[Season],Games[[#This Row],[Season]],Games[Week],Games[[#This Row],[PrevWeekTeam]]))) | W5: =IF(Games[[#This Row],[Team]]="","",IF(Games[[#This Row],[PrevWeekOpp]]=0,"",Games[[#This Row],[Date]]-SUMIFS(Games[Date],Games[Team],Games[[#This Row],[Opponent]],Games[Season],Games[[#This Row],[Season]],Games[Week],Games[[#This Row],[PrevWeekOpp]]))) | X5: =IF(Games[[#This Row],[Team]]="","",IF(OR(Games[[#This Row],[DaysOff]]="",Games[[#This Row],[OppDaysOff]]=""),0,IF(Games[[#This Row],[DaysOff]]-Games[[#This Row],[OppDaysOff]]=0,0,IF(ABS(Games[[#This Row],[DaysOff]]-Games[[#This Row],[OppDaysOff]])>=6,IF(Games[[#This Row],[DaysOff]]-Games[[#This Row],[OppDaysOff]]>0,RestMajor,-RestMajor),IF(Games[[#This Row],[DaysOff]]-Games[[#This Row],[OppDaysOff]]>0,RestMinor,-RestMinor))))) -> 0 | Y5: =IF(Games[[#This Row],[Team]]="","",IF(Games[[#This Row],[PrevWeekTeam]]>0,SUMIFS(Games[PostGmRate],Games[Team],Games[[#This Row],[Team]],Games[Season],Games[[#This Row],[Season]],Games[Week],Games[[#This Row],[PrevWeekTeam]]),Alpha*IFERROR(INDEX(Teams[PreseasonRating],MATCH(Games[[#This Row],[Team]],Teams[TeamID],0)),Base)+(1-Alpha)*Base)) -> 1500 | Z5: =IF(Games[[#This Row],[Team]]="","",IF(Games[[#This Row],[PrevWeekOpp]]>0,SUMIFS(Games[PostGmRate],Games[Team],Games[[#This Row],[Opponent]],Games[Season],Games[[#This Row],[Season]],Games[Week],Games[[#This Row],[PrevWeekOpp]]),Alpha*IFERROR(INDEX(Teams[PreseasonRating],MATCH(Games[[#This Row],[Opponent]],Teams[TeamID],0)),Base)+(1-Alpha)*Base)) -> 1500 | AA5: =IF(Games[[#This Row],[Team]]="","",1/(1+10^(((Games[[#This Row],[OppPreGmRate]]+IF(Games[[#This Row],[HomeAway]]="A",HFA-Games[[#This Row],[RestAdj]],0))-(Games[[#This Row],[PreGmRate]]+IF(Games[[#This Row],[HomeAway]]="H",HFA+Games[[#This Row],[RestAdj]],0)))/400))) -> 0.39784191 | AB5: =IF(Games[[#This Row],[Team]]="","",Games[[#This Row],[PointsFor]]-Games[[#This Row],[PointsAgainst]]) -> -10 | AC5: =IF(Games[[#This Row],[Team]]="","",IF(Games[[#This Row],[MOV]]>0,1,IF(Games[[#This Row],[MOV]]=0,0.5,0))) -> 0 | AD5: =IF(Games[[#This Row],[Team]]="","",--(OR(AND(Games[[#This Row],[ExpectedWin]]>=0.5,Games[[#This Row],[Result]]=1),AND(Games[[#This Row],[ExpectedWin]]<0.5,Games[[#This Row],[Result]]=0)))) -> 1 | AE5: =IF(Games[[#This Row],[Team]]="","",-(Games[[#This Row],[Result]]*LN(Games[[#This Row],[ExpectedWin]])+(1-Games[[#This Row],[Result]])*LN(1-Games[[#This Row],[ExpectedWin]]))) -> 0.50723525 | AF5: =IF(Games[[#This Row],[Team]]="","",IF(Games[[#This Row],[Season]]>=2021,17,16)) -> 16 | AG5: =IF(Games[[#This Row],[Team]]="","",KMax-(KMax-KFloor)*MIN(Games[[#This Row],[GamesPlayed]],Games[[#This Row],[SeasonLen]])/Games[[#This Row],[SeasonLen]]) -> 45.3875 | AH5: =IF(Games[[#This Row],[Team]]="","",((ABS(Games[[#This Row],[MOV]])+3)^0.8)/(7.5+0.006*ABS(Games[[#This Row],[PreGmRate]]-Games[[#This Row],[OppPreGmRate]]))*IF(Games[[#This Row],[OT]]=1,0.7,1)) -> 1.0377516 | AI5: =IF(Games[[#This Row],[Team]]="","",IF(Games[[#This Row],[Type]]="P",_xlfn.IFS(Games[[#This Row],[Round]]="WC",POMult_WC,Games[[#This Row],[Round]]="DV",POMult_DV,Games[[#This Row],[Round]]="CC",POMult_CC,Games[[#This Row],[Round]]="SB",POMult_SB,TRUE,1),1)) -> 1 | AJ5: =IF(Games[[#This Row],[Team]]="","",Games[[#This Row],[K]]*IF(Games[[#This Row],[DivG]]=1,DivMult,1)*IF(Games[[#This Row],[ConfG]]=1,ConfMult,1)*Games[[#This Row],[POMult]]) -> 45.3875 | AK5: =IF(Games[[#This Row],[Team]]="","",(Games[[#This Row],[Keff]]*Games[[#This Row],[MOVMult]])*(Games[[#This Row],[Result]]-Games[[#This Row],[ExpectedWin]])) -> -18.738732 | AL5: =IF(Games[[#This Row],[Team]]="","",Games[[#This Row],[PreGmRate]]+Games[[#This Row],[RatingChange]]) -> 1481.2613 | AM5: =IF(Games[[#This Row],[Team]]="","",IF(Games[[#This Row],[Type]]="R",IF(Games[[#This Row],[Result]]>0.5,1,0),0)) -> 0 | AN5: =IF(Games[[#This Row],[Team]]="","",IF(Games[[#This Row],[Type]]="R",IF(Games[[#This Row],[Result]]<0.5,1,0),0)) -> 1 | AO5: =IF(Games[[#This Row],[Team]]="","",IF(Games[[#This Row],[Type]]="R",IF(Games[[#This Row],[Result]]=0.5,1,0),0)) -> 0
A6: 35309 | B6: 1996 | C6: R | D6: RS | E6: IND | F6: ARI | G6: H | H6: 20 | I6: 13 | J6: 0 | K6: =IF(Games[[#This Row],[Team]]="","",IF(Games[[#This Row],[Season]]>2001,IFERROR(INDEX(Teams[Conf],MATCH(Games[[#This Row],[Team]],Teams[TeamID],0)),"NEW"),IFERROR(INDEX(Teams[Pre02Conf],MATCH(Games[[#This Row],[Team]],Teams[TeamID],0)),"NEW"))) -> AFC | L6: =IF(Games[[#This Row],[Team]]="","",IF(Games[[#This Row],[Season]]>2001,IFERROR(INDEX(Teams[Conf],MATCH(Games[[#This Row],[Opponent]],Teams[TeamID],0)),"NEW"),IFERROR(INDEX(Teams[Pre02Conf],MATCH(Games[[#This Row],[Opponent]],Teams[TeamID],0)),"NEW"))) -> NFC | M6: =IF(Games[[#This Row],[Team]]="","",IF(Games[[#This Row],[Season]]>2001,IFERROR(INDEX(Teams[Div],MATCH(Games[[#This Row],[Team]],Teams[TeamID],0)),"NEW"),IFERROR(INDEX(Teams[Pre02Div],MATCH(Games[[#This Row],[Team]],Teams[TeamID],0)),"NEW"))) -> East | N6: =IF(Games[[#This Row],[Team]]="","",IF(Games[[#This Row],[Season]]>2001,IFERROR(INDEX(Teams[Div],MATCH(Games[[#This Row],[Opponent]],Teams[TeamID],0)),"NEW"),IFERROR(INDEX(Teams[Pre02Div],MATCH(Games[[#This Row],[Opponent]],Teams[TeamID],0)),"NEW"))) -> East | O6: =IF(Games[[#This Row],[Team]]="","",IF(Games[[#This Row],[Conf]]=Games[[#This Row],[OppConf]],1,0)) -> 0 | P6: =IF(Games[[#This Row],[Team]]="","",IF(AND(Games[[#This Row],[Conf]]=Games[[#This Row],[OppConf]],Games[[#This Row],[Div]]=Games[[#This Row],[OppDiv]]),1,0)) -> 0 | Q6: =IF(Games[[#This Row],[Team]]="","",_xlfn.MINIFS(Games[Date],Games[Season],Games[[#This Row],[Season]])) -> 35309 | R6: =IF(Games[[#This Row],[Team]]="","",INT((Games[[#This Row],[Date]]-(Games[[#This Row],[SeasonStart]]-MOD(WEEKDAY(Games[[#This Row],[SeasonStart]],2)-2,7)))/7)+1) -> 1 | S6: =IF(Games[[#This Row],[Team]]="","",COUNTIFS(Games[Team],Games[[#This Row],[Team]],Games[Season],Games[[#This Row],[Season]],Games[Week],"<="&Games[[#This Row],[Week]])) -> 1 | T6: =IF(Games[[#This Row],[Team]]="","",_xlfn.MAXIFS(Games[Week],Games[Team],Games[[#This Row],[Team]],Games[Season],Games[[#This Row],[Season]],Games[Week],"<"&Games[[#This Row],[Week]])) -> 0 | U6: =IF(Games[[#This Row],[Team]]="","",_xlfn.MAXIFS(Games[Week],Games[Team],Games[[#This Row],[Opponent]],Games[Season],Games[[#This Row],[Season]],Games[Week],"<"&Games[[#This Row],[Week]])) -> 0 | V6: =IF(Games[[#This Row],[Team]]="","",IF(Games[[#This Row],[PrevWeekTeam]]=0,"",Games[[#This Row],[Date]]-SUMIFS(Games[Date],Games[Team],Games[[#This Row],[Team]],Games[Season],Games[[#This Row],[Season]],Games[Week],Games[[#This Row],[PrevWeekTeam]]))) | W6: =IF(Games[[#This Row],[Team]]="","",IF(Games[[#This Row],[PrevWeekOpp]]=0,"",Games[[#This Row],[Date]]-SUMIFS(Games[Date],Games[Team],Games[[#This Row],[Opponent]],Games[Season],Games[[#This Row],[Season]],Games[Week],Games[[#This Row],[PrevWeekOpp]]))) | X6: =IF(Games[[#This Row],[Team]]="","",IF(OR(Games[[#This Row],[DaysOff]]="",Games[[#This Row],[OppDaysOff]]=""),0,IF(Games[[#This Row],[DaysOff]]-Games[[#This Row],[OppDaysOff]]=0,0,IF(ABS(Games[[#This Row],[DaysOff]]-Games[[#This Row],[OppDaysOff]])>=6,IF(Games[[#This Row],[DaysOff]]-Games[[#This Row],[OppDaysOff]]>0,RestMajor,-RestMajor),IF(Games[[#This Row],[DaysOff]]-Games[[#This Row],[OppDaysOff]]>0,RestMinor,-RestMinor))))) -> 0 | Y6: =IF(Games[[#This Row],[Team]]="","",IF(Games[[#This Row],[PrevWeekTeam]]>0,SUMIFS(Games[PostGmRate],Games[Team],Games[[#This Row],[Team]],Games[Season],Games[[#This Row],[Season]],Games[Week],Games[[#This Row],[PrevWeekTeam]]),Alpha*IFERROR(INDEX(Teams[PreseasonRating],MATCH(Games[[#This Row],[Team]],Teams[TeamID],0)),Base)+(1-Alpha)*Base)) -> 1500 | Z6: =IF(Games[[#This Row],[Team]]="","",IF(Games[[#This Row],[PrevWeekOpp]]>0,SUMIFS(Games[PostGmRate],Games[Team],Games[[#This Row],[Opponent]],Games[Season],Games[[#This Row],[Season]],Games[Week],Games[[#This Row],[PrevWeekOpp]]),Alpha*IFERROR(INDEX(Teams[PreseasonRating],MATCH(Games[[#This Row],[Opponent]],Teams[TeamID],0)),Base)+(1-Alpha)*Base)) -> 1500 | AA6: =IF(Games[[#This Row],[Team]]="","",1/(1+10^(((Games[[#This Row],[OppPreGmRate]]+IF(Games[[#This Row],[HomeAway]]="A",HFA-Games[[#This Row],[RestAdj]],0))-(Games[[#This Row],[PreGmRate]]+IF(Games[[#This Row],[HomeAway]]="H",HFA+Games[[#This Row],[RestAdj]],0)))/400))) -> 0.60215809 | AB6: =IF(Games[[#This Row],[Team]]="","",Games[[#This Row],[PointsFor]]-Games[[#This Row],[PointsAgainst]]) -> 7 | AC6: =IF(Games[[#This Row],[Team]]="","",IF(Games[[#This Row],[MOV]]>0,1,IF(Games[[#This Row],[MOV]]=0,0.5,0))) -> 1 | AD6: =IF(Games[[#This Row],[Team]]="","",--(OR(AND(Games[[#This Row],[ExpectedWin]]>=0.5,Games[[#This Row],[Result]]=1),AND(Games[[#This Row],[ExpectedWin]]<0.5,Games[[#This Row],[Result]]=0)))) -> 1 | AE6: =IF(Games[[#This Row],[Team]]="","",-(Games[[#This Row],[Result]]*LN(Games[[#This Row],[ExpectedWin]])+(1-Games[[#This Row],[Result]])*LN(1-Games[[#This Row],[ExpectedWin]]))) -> 0.50723525 | AF6: =IF(Games[[#This Row],[Team]]="","",IF(Games[[#This Row],[Season]]>=2021,17,16)) -> 16 | AG6: =IF(Games[[#This Row],[Team]]="","",KMax-(KMax-KFloor)*MIN(Games[[#This Row],[GamesPlayed]],Games[[#This Row],[SeasonLen]])/Games[[#This Row],[SeasonLen]]) -> 45.3875 | AH6: =IF(Games[[#This Row],[Team]]="","",((ABS(Games[[#This Row],[MOV]])+3)^0.8)/(7.5+0.006*ABS(Games[[#This Row],[PreGmRate]]-Games[[#This Row],[OppPreGmRate]]))*IF(Games[[#This Row],[OT]]=1,0.7,1)) -> 0.84127646 | AI6: =IF(Games[[#This Row],[Team]]="","",IF(Games[[#This Row],[Type]]="P",_xlfn.IFS(Games[[#This Row],[Round]]="WC",POMult_WC,Games[[#This Row],[Round]]="DV",POMult_DV,Games[[#This Row],[Round]]="CC",POMult_CC,Games[[#This Row],[Round]]="SB",POMult_SB,TRUE,1),1)) -> 1 | AJ6: =IF(Games[[#This Row],[Team]]="","",Games[[#This Row],[K]]*IF(Games[[#This Row],[DivG]]=1,DivMult,1)*IF(Games[[#This Row],[ConfG]]=1,ConfMult,1)*Games[[#This Row],[POMult]]) -> 45.3875 | AK6: =IF(Games[[#This Row],[Team]]="","",(Games[[#This Row],[Keff]]*Games[[#This Row],[MOVMult]])*(Games[[#This Row],[Result]]-Games[[#This Row],[ExpectedWin]])) -> 15.190971 | AL6: =IF(Games[[#This Row],[Team]]="","",Games[[#This Row],[PreGmRate]]+Games[[#This Row],[RatingChange]]) -> 1515.191 | AM6: =IF(Games[[#This Row],[Team]]="","",IF(Games[[#This Row],[Type]]="R",IF(Games[[#This Row],[Result]]>0.5,1,0),0)) -> 1 | AN6: =IF(Games[[#This Row],[Team]]="","",IF(Games[[#This Row],[Type]]="R",IF(Games[[#This Row],[Result]]<0.5,1,0),0)) -> 0 | AO6: =IF(Games[[#This Row],[Team]]="","",IF(Games[[#This Row],[Type]]="R",IF(Games[[#This Row],[Result]]=0.5,1,0),0)) -> 0
A7: 35309 | B7: 1996 | C7: R | D7: RS | E7: ARI | F7: IND | G7: A | H7: 13 | I7: 20 | J7: 0 | K7: =IF(Games[[#This Row],[Team]]="","",IF(Games[[#This Row],[Season]]>2001,IFERROR(INDEX(Teams[Conf],MATCH(Games[[#This Row],[Team]],Teams[TeamID],0)),"NEW"),IFERROR(INDEX(Teams[Pre02Conf],MATCH(Games[[#This Row],[Team]],Teams[TeamID],0)),"NEW"))) -> NFC | L7: =IF(Games[[#This Row],[Team]]="","",IF(Games[[#This Row],[Season]]>2001,IFERROR(INDEX(Teams[Conf],MATCH(Games[[#This Row],[Opponent]],Teams[TeamID],0)),"NEW"),IFERROR(INDEX(Teams[Pre02Conf],MATCH(Games[[#This Row],[Opponent]],Teams[TeamID],0)),"NEW"))) -> AFC | M7: =IF(Games[[#This Row],[Team]]="","",IF(Games[[#This Row],[Season]]>2001,IFERROR(INDEX(Teams[Div],MATCH(Games[[#This Row],[Team]],Teams[TeamID],0)),"NEW"),IFERROR(INDEX(Teams[Pre02Div],MATCH(Games[[#This Row],[Team]],Teams[TeamID],0)),"NEW"))) -> East | N7: =IF(Games[[#This Row],[Team]]="","",IF(Games[[#This Row],[Season]]>2001,IFERROR(INDEX(Teams[Div],MATCH(Games[[#This Row],[Opponent]],Teams[TeamID],0)),"NEW"),IFERROR(INDEX(Teams[Pre02Div],MATCH(Games[[#This Row],[Opponent]],Teams[TeamID],0)),"NEW"))) -> East | O7: =IF(Games[[#This Row],[Team]]="","",IF(Games[[#This Row],[Conf]]=Games[[#This Row],[OppConf]],1,0)) -> 0 | P7: =IF(Games[[#This Row],[Team]]="","",IF(AND(Games[[#This Row],[Conf]]=Games[[#This Row],[OppConf]],Games[[#This Row],[Div]]=Games[[#This Row],[OppDiv]]),1,0)) -> 0 | Q7: =IF(Games[[#This Row],[Team]]="","",_xlfn.MINIFS(Games[Date],Games[Season],Games[[#This Row],[Season]])) -> 35309 | R7: =IF(Games[[#This Row],[Team]]="","",INT((Games[[#This Row],[Date]]-(Games[[#This Row],[SeasonStart]]-MOD(WEEKDAY(Games[[#This Row],[SeasonStart]],2)-2,7)))/7)+1) -> 1 | S7: =IF(Games[[#This Row],[Team]]="","",COUNTIFS(Games[Team],Games[[#This Row],[Team]],Games[Season],Games[[#This Row],[Season]],Games[Week],"<="&Games[[#This Row],[Week]])) -> 1 | T7: =IF(Games[[#This Row],[Team]]="","",_xlfn.MAXIFS(Games[Week],Games[Team],Games[[#This Row],[Team]],Games[Season],Games[[#This Row],[Season]],Games[Week],"<"&Games[[#This Row],[Week]])) -> 0 | U7: =IF(Games[[#This Row],[Team]]="","",_xlfn.MAXIFS(Games[Week],Games[Team],Games[[#This Row],[Opponent]],Games[Season],Games[[#This Row],[Season]],Games[Week],"<"&Games[[#This Row],[Week]])) -> 0 | V7: =IF(Games[[#This Row],[Team]]="","",IF(Games[[#This Row],[PrevWeekTeam]]=0,"",Games[[#This Row],[Date]]-SUMIFS(Games[Date],Games[Team],Games[[#This Row],[Team]],Games[Season],Games[[#This Row],[Season]],Games[Week],Games[[#This Row],[PrevWeekTeam]]))) | W7: =IF(Games[[#This Row],[Team]]="","",IF(Games[[#This Row],[PrevWeekOpp]]=0,"",Games[[#This Row],[Date]]-SUMIFS(Games[Date],Games[Team],Games[[#This Row],[Opponent]],Games[Season],Games[[#This Row],[Season]],Games[Week],Games[[#This Row],[PrevWeekOpp]]))) | X7: =IF(Games[[#This Row],[Team]]="","",IF(OR(Games[[#This Row],[DaysOff]]="",Games[[#This Row],[OppDaysOff]]=""),0,IF(Games[[#This Row],[DaysOff]]-Games[[#This Row],[OppDaysOff]]=0,0,IF(ABS(Games[[#This Row],[DaysOff]]-Games[[#This Row],[OppDaysOff]])>=6,IF(Games[[#This Row],[DaysOff]]-Games[[#This Row],[OppDaysOff]]>0,RestMajor,-RestMajor),IF(Games[[#This Row],[DaysOff]]-Games[[#This Row],[OppDaysOff]]>0,RestMinor,-RestMinor))))) -> 0 | Y7: =IF(Games[[#This Row],[Team]]="","",IF(Games[[#This Row],[PrevWeekTeam]]>0,SUMIFS(Games[PostGmRate],Games[Team],Games[[#This Row],[Team]],Games[Season],Games[[#This Row],[Season]],Games[Week],Games[[#This Row],[PrevWeekTeam]]),Alpha*IFERROR(INDEX(Teams[PreseasonRating],MATCH(Games[[#This Row],[Team]],Teams[TeamID],0)),Base)+(1-Alpha)*Base)) -> 1500 | Z7: =IF(Games[[#This Row],[Team]]="","",IF(Games[[#This Row],[PrevWeekOpp]]>0,SUMIFS(Games[PostGmRate],Games[Team],Games[[#This Row],[Opponent]],Games[Season],Games[[#This Row],[Season]],Games[Week],Games[[#This Row],[PrevWeekOpp]]),Alpha*IFERROR(INDEX(Teams[PreseasonRating],MATCH(Games[[#This Row],[Opponent]],Teams[TeamID],0)),Base)+(1-Alpha)*Base)) -> 1500 | AA7: =IF(Games[[#This Row],[Team]]="","",1/(1+10^(((Games[[#This Row],[OppPreGmRate]]+IF(Games[[#This Row],[HomeAway]]="A",HFA-Games[[#This Row],[RestAdj]],0))-(Games[[#This Row],[PreGmRate]]+IF(Games[[#This Row],[HomeAway]]="H",HFA+Games[[#This Row],[RestAdj]],0)))/400))) -> 0.39784191 | AB7: =IF(Games[[#This Row],[Team]]="","",Games[[#This Row],[PointsFor]]-Games[[#This Row],[PointsAgainst]]) -> -7 | AC7: =IF(Games[[#This Row],[Team]]="","",IF(Games[[#This Row],[MOV]]>0,1,IF(Games[[#This Row],[MOV]]=0,0.5,0))) -> 0 | AD7: =IF(Games[[#This Row],[Team]]="","",--(OR(AND(Games[[#This Row],[ExpectedWin]]>=0.5,Games[[#This Row],[Result]]=1),AND(Games[[#This Row],[ExpectedWin]]<0.5,Games[[#This Row],[Result]]=0)))) -> 1 | AE7: =IF(Games[[#This Row],[Team]]="","",-(Games[[#This Row],[Result]]*LN(Games[[#This Row],[ExpectedWin]])+(1-Games[[#This Row],[Result]])*LN(1-Games[[#This Row],[ExpectedWin]]))) -> 0.50723525 | AF7: =IF(Games[[#This Row],[Team]]="","",IF(Games[[#This Row],[Season]]>=2021,17,16)) -> 16 | AG7: =IF(Games[[#This Row],[Team]]="","",KMax-(KMax-KFloor)*MIN(Games[[#This Row],[GamesPlayed]],Games[[#This Row],[SeasonLen]])/Games[[#This Row],[SeasonLen]]) -> 45.3875 | AH7: =IF(Games[[#This Row],[Team]]="","",((ABS(Games[[#This Row],[MOV]])+3)^0.8)/(7.5+0.006*ABS(Games[[#This Row],[PreGmRate]]-Games[[#This Row],[OppPreGmRate]]))*IF(Games[[#This Row],[OT]]=1,0.7,1)) -> 0.84127646 | AI7: =IF(Games[[#This Row],[Team]]="","",IF(Games[[#This Row],[Type]]="P",_xlfn.IFS(Games[[#This Row],[Round]]="WC",POMult_WC,Games[[#This Row],[Round]]="DV",POMult_DV,Games[[#This Row],[Round]]="CC",POMult_CC,Games[[#This Row],[Round]]="SB",POMult_SB,TRUE,1),1)) -> 1 | AJ7: =IF(Games[[#This Row],[Team]]="","",Games[[#This Row],[K]]*IF(Games[[#This Row],[DivG]]=1,DivMult,1)*IF(Games[[#This Row],[ConfG]]=1,ConfMult,1)*Games[[#This Row],[POMult]]) -> 45.3875 | AK7: =IF(Games[[#This Row],[Team]]="","",(Games[[#This Row],[Keff]]*Games[[#This Row],[MOVMult]])*(Games[[#This Row],[Result]]-Games[[#This Row],[ExpectedWin]])) -> -15.190971 | AL7: =IF(Games[[#This Row],[Team]]="","",Games[[#This Row],[PreGmRate]]+Games[[#This Row],[RatingChange]]) -> 1484.809 | AM7: =IF(Games[[#This Row],[Team]]="","",IF(Games[[#This Row],[Type]]="R",IF(Games[[#This Row],[Result]]>0.5,1,0),0)) -> 0 | AN7: =IF(Games[[#This Row],[Team]]="","",IF(Games[[#This Row],[Type]]="R",IF(Games[[#This Row],[Result]]<0.5,1,0),0)) -> 1 | AO7: =IF(Games[[#This Row],[Team]]="","",IF(Games[[#This Row],[Type]]="R",IF(Games[[#This Row],[Result]]=0.5,1,0),0)) -> 0
A8: 35309 | B8: 1996 | C8: R | D8: RS | E8: MIN | F8: DET | G8: H | H8: 17 | I8: 13 | J8: 0 | K8: =IF(Games[[#This Row],[Team]]="","",IF(Games[[#This Row],[Season]]>2001,IFERROR(INDEX(Teams[Conf],MATCH(Games[[#This Row],[Team]],Teams[TeamID],0)),"NEW"),IFERROR(INDEX(Teams[Pre02Conf],MATCH(Games[[#This Row],[Team]],Teams[TeamID],0)),"NEW"))) -> NFC | L8: =IF(Games[[#This Row],[Team]]="","",IF(Games[[#This Row],[Season]]>2001,IFERROR(INDEX(Teams[Conf],MATCH(Games[[#This Row],[Opponent]],Teams[TeamID],0)),"NEW"),IFERROR(INDEX(Teams[Pre02Conf],MATCH(Games[[#This Row],[Opponent]],Teams[TeamID],0)),"NEW"))) -> NFC | M8: =IF(Games[[#This Row],[Team]]="","",IF(Games[[#This Row],[Season]]>2001,IFERROR(INDEX(Teams[Div],MATCH(Games[[#This Row],[Team]],Teams[TeamID],0)),"NEW"),IFERROR(INDEX(Teams[Pre02Div],MATCH(Games[[#This Row],[Team]],Teams[TeamID],0)),"NEW"))) -> Central | N8: =IF(Games[[#This Row],[Team]]="","",IF(Games[[#This Row],[Season]]>2001,IFERROR(INDEX(Teams[Div],MATCH(Games[[#This Row],[Opponent]],Teams[TeamID],0)),"NEW"),IFERROR(INDEX(Teams[Pre02Div],MATCH(Games[[#This Row],[Opponent]],Teams[TeamID],0)),"NEW"))) -> Central | O8: =IF(Games[[#This Row],[Team]]="","",IF(Games[[#This Row],[Conf]]=Games[[#This Row],[OppConf]],1,0)) -> 1 | P8: =IF(Games[[#This Row],[Team]]="","",IF(AND(Games[[#This Row],[Conf]]=Games[[#This Row],[OppConf]],Games[[#This Row],[Div]]=Games[[#This Row],[OppDiv]]),1,0)) -> 1 | Q8: =IF(Games[[#This Row],[Team]]="","",_xlfn.MINIFS(Games[Date],Games[Season],Games[[#This Row],[Season]])) -> 35309 | R8: =IF(Games[[#This Row],[Team]]="","",INT((Games[[#This Row],[Date]]-(Games[[#This Row],[SeasonStart]]-MOD(WEEKDAY(Games[[#This Row],[SeasonStart]],2)-2,7)))/7)+1) -> 1 | S8: =IF(Games[[#This Row],[Team]]="","",COUNTIFS(Games[Team],Games[[#This Row],[Team]],Games[Season],Games[[#This Row],[Season]],Games[Week],"<="&Games[[#This Row],[Week]])) -> 1 | T8: =IF(Games[[#This Row],[Team]]="","",_xlfn.MAXIFS(Games[Week],Games[Team],Games[[#This Row],[Team]],Games[Season],Games[[#This Row],[Season]],Games[Week],"<"&Games[[#This Row],[Week]])) -> 0 | U8: =IF(Games[[#This Row],[Team]]="","",_xlfn.MAXIFS(Games[Week],Games[Team],Games[[#This Row],[Opponent]],Games[Season],Games[[#This Row],[Season]],Games[Week],"<"&Games[[#This Row],[Week]])) -> 0 | V8: =IF(Games[[#This Row],[Team]]="","",IF(Games[[#This Row],[PrevWeekTeam]]=0,"",Games[[#This Row],[Date]]-SUMIFS(Games[Date],Games[Team],Games[[#This Row],[Team]],Games[Season],Games[[#This Row],[Season]],Games[Week],Games[[#This Row],[PrevWeekTeam]]))) | W8: =IF(Games[[#This Row],[Team]]="","",IF(Games[[#This Row],[PrevWeekOpp]]=0,"",Games[[#This Row],[Date]]-SUMIFS(Games[Date],Games[Team],Games[[#This Row],[Opponent]],Games[Season],Games[[#This Row],[Season]],Games[Week],Games[[#This Row],[PrevWeekOpp]]))) | X8: =IF(Games[[#This Row],[Team]]="","",IF(OR(Games[[#This Row],[DaysOff]]="",Games[[#This Row],[OppDaysOff]]=""),0,IF(Games[[#This Row],[DaysOff]]-Games[[#This Row],[OppDaysOff]]=0,0,IF(ABS(Games[[#This Row],[DaysOff]]-Games[[#This Row],[OppDaysOff]])>=6,IF(Games[[#This Row],[DaysOff]]-Games[[#This Row],[OppDaysOff]]>0,RestMajor,-RestMajor),IF(Games[[#This Row],[DaysOff]]-Games[[#This Row],[OppDaysOff]]>0,RestMinor,-RestMinor))))) -> 0 | Y8: =IF(Games[[#This Row],[Team]]="","",IF(Games[[#This Row],[PrevWeekTeam]]>0,SUMIFS(Games[PostGmRate],Games[Team],Games[[#This Row],[Team]],Games[Season],Games[[#This Row],[Season]],Games[Week],Games[[#This Row],[PrevWeekTeam]]),Alpha*IFERROR(INDEX(Teams[PreseasonRating],MATCH(Games[[#This Row],[Team]],Teams[TeamID],0)),Base)+(1-Alpha)*Base)) -> 1500 | Z8: =IF(Games[[#This Row],[Team]]="","",IF(Games[[#This Row],[PrevWeekOpp]]>0,SUMIFS(Games[PostGmRate],Games[Team],Games[[#This Row],[Opponent]],Games[Season],Games[[#This Row],[Season]],Games[Week],Games[[#This Row],[PrevWeekOpp]]),Alpha*IFERROR(INDEX(Teams[PreseasonRating],MATCH(Games[[#This Row],[Opponent]],Teams[TeamID],0)),Base)+(1-Alpha)*Base)) -> 1500 | AA8: =IF(Games[[#This Row],[Team]]="","",1/(1+10^(((Games[[#This Row],[OppPreGmRate]]+IF(Games[[#This Row],[HomeAway]]="A",HFA-Games[[#This Row],[RestAdj]],0))-(Games[[#This Row],[PreGmRate]]+IF(Games[[#This Row],[HomeAway]]="H",HFA+Games[[#This Row],[RestAdj]],0)))/400))) -> 0.60215809 | AB8: =IF(Games[[#This Row],[Team]]="","",Games[[#This Row],[PointsFor]]-Games[[#This Row],[PointsAgainst]]) -> 4 | AC8: =IF(Games[[#This Row],[Team]]="","",IF(Games[[#This Row],[MOV]]>0,1,IF(Games[[#This Row],[MOV]]=0,0.5,0))) -> 1 | AD8: =IF(Games[[#This Row],[Team]]="","",--(OR(AND(Games[[#This Row],[ExpectedWin]]>=0.5,Games[[#This Row],[Result]]=1),AND(Games[[#This Row],[ExpectedWin]]<0.5,Games[[#This Row],[Result]]=0)))) -> 1 | AE8: =IF(Games[[#This Row],[Team]]="","",-(Games[[#This Row],[Result]]*LN(Games[[#This Row],[ExpectedWin]])+(1-Games[[#This Row],[Result]])*LN(1-Games[[#This Row],[ExpectedWin]]))) -> 0.50723525 | AF8: =IF(Games[[#This Row],[Team]]="","",IF(Games[[#This Row],[Season]]>=2021,17,16)) -> 16 | AG8: =IF(Games[[#This Row],[Team]]="","",KMax-(KMax-KFloor)*MIN(Games[[#This Row],[GamesPlayed]],Games[[#This Row],[SeasonLen]])/Games[[#This Row],[SeasonLen]]) -> 45.3875 | AH8: =IF(Games[[#This Row],[Team]]="","",((ABS(Games[[#This Row],[MOV]])+3)^0.8)/(7.5+0.006*ABS(Games[[#This Row],[PreGmRate]]-Games[[#This Row],[OppPreGmRate]]))*IF(Games[[#This Row],[OT]]=1,0.7,1)) -> 0.63243685 | AI8: =IF(Games[[#This Row],[Team]]="","",IF(Games[[#This Row],[Type]]="P",_xlfn.IFS(Games[[#This Row],[Round]]="WC",POMult_WC,Games[[#This Row],[Round]]="DV",POMult_DV,Games[[#This Row],[Round]]="CC",POMult_CC,Games[[#This Row],[Round]]="SB",POMult_SB,TRUE,1),1)) -> 1 | AJ8: =IF(Games[[#This Row],[Team]]="","",Games[[#This Row],[K]]*IF(Games[[#This Row],[DivG]]=1,DivMult,1)*IF(Games[[#This Row],[ConfG]]=1,ConfMult,1)*Games[[#This Row],[POMult]]) -> 50.924775 | AK8: =IF(Games[[#This Row],[Team]]="","",(Games[[#This Row],[Keff]]*Games[[#This Row],[MOVMult]])*(Games[[#This Row],[Result]]-Games[[#This Row],[ExpectedWin]])) -> 12.813177 | AL8: =IF(Games[[#This Row],[Team]]="","",Games[[#This Row],[PreGmRate]]+Games[[#This Row],[RatingChange]]) -> 1512.8132 | AM8: =IF(Games[[#This Row],[Team]]="","",IF(Games[[#This Row],[Type]]="R",IF(Games[[#This Row],[Result]]>0.5,1,0),0)) -> 1 | AN8: =IF(Games[[#This Row],[Team]]="","",IF(Games[[#This Row],[Type]]="R",IF(Games[[#This Row],[Result]]<0.5,1,0),0)) -> 0 | AO8: =IF(Games[[#This Row],[Team]]="","",IF(Games[[#This Row],[Type]]="R",IF(Games[[#This Row],[Result]]=0.5,1,0),0)) -> 0
A9: 35309 | B9: 1996 | C9: R | D9: RS | E9: DET | F9: MIN | G9: A | H9: 13 | I9: 17 | J9: 0 | K9: =IF(Games[[#This Row],[Team]]="","",IF(Games[[#This Row],[Season]]>2001,IFERROR(INDEX(Teams[Conf],MATCH(Games[[#This Row],[Team]],Teams[TeamID],0)),"NEW"),IFERROR(INDEX(Teams[Pre02Conf],MATCH(Games[[#This Row],[Team]],Teams[TeamID],0)),"NEW"))) -> NFC | L9: =IF(Games[[#This Row],[Team]]="","",IF(Games[[#This Row],[Season]]>2001,IFERROR(INDEX(Teams[Conf],MATCH(Games[[#This Row],[Opponent]],Teams[TeamID],0)),"NEW"),IFERROR(INDEX(Teams[Pre02Conf],MATCH(Games[[#This Row],[Opponent]],Teams[TeamID],0)),"NEW"))) -> NFC | M9: =IF(Games[[#This Row],[Team]]="","",IF(Games[[#This Row],[Season]]>2001,IFERROR(INDEX(Teams[Div],MATCH(Games[[#This Row],[Team]],Teams[TeamID],0)),"NEW"),IFERROR(INDEX(Teams[Pre02Div],MATCH(Games[[#This Row],[Team]],Teams[TeamID],0)),"NEW"))) -> Central | N9: =IF(Games[[#This Row],[Team]]="","",IF(Games[[#This Row],[Season]]>2001,IFERROR(INDEX(Teams[Div],MATCH(Games[[#This Row],[Opponent]],Teams[TeamID],0)),"NEW"),IFERROR(INDEX(Teams[Pre02Div],MATCH(Games[[#This Row],[Opponent]],Teams[TeamID],0)),"NEW"))) -> Central | O9: =IF(Games[[#This Row],[Team]]="","",IF(Games[[#This Row],[Conf]]=Games[[#This Row],[OppConf]],1,0)) -> 1 | P9: =IF(Games[[#This Row],[Team]]="","",IF(AND(Games[[#This Row],[Conf]]=Games[[#This Row],[OppConf]],Games[[#This Row],[Div]]=Games[[#This Row],[OppDiv]]),1,0)) -> 1 | Q9: =IF(Games[[#This Row],[Team]]="","",_xlfn.MINIFS(Games[Date],Games[Season],Games[[#This Row],[Season]])) -> 35309 | R9: =IF(Games[[#This Row],[Team]]="","",INT((Games[[#This Row],[Date]]-(Games[[#This Row],[SeasonStart]]-MOD(WEEKDAY(Games[[#This Row],[SeasonStart]],2)-2,7)))/7)+1) -> 1 | S9: =IF(Games[[#This Row],[Team]]="","",COUNTIFS(Games[Team],Games[[#This Row],[Team]],Games[Season],Games[[#This Row],[Season]],Games[Week],"<="&Games[[#This Row],[Week]])) -> 1 | T9: =IF(Games[[#This Row],[Team]]="","",_xlfn.MAXIFS(Games[Week],Games[Team],Games[[#This Row],[Team]],Games[Season],Games[[#This Row],[Season]],Games[Week],"<"&Games[[#This Row],[Week]])) -> 0 | U9: =IF(Games[[#This Row],[Team]]="","",_xlfn.MAXIFS(Games[Week],Games[Team],Games[[#This Row],[Opponent]],Games[Season],Games[[#This Row],[Season]],Games[Week],"<"&Games[[#This Row],[Week]])) -> 0 | V9: =IF(Games[[#This Row],[Team]]="","",IF(Games[[#This Row],[PrevWeekTeam]]=0,"",Games[[#This Row],[Date]]-SUMIFS(Games[Date],Games[Team],Games[[#This Row],[Team]],Games[Season],Games[[#This Row],[Season]],Games[Week],Games[[#This Row],[PrevWeekTeam]]))) | W9: =IF(Games[[#This Row],[Team]]="","",IF(Games[[#This Row],[PrevWeekOpp]]=0,"",Games[[#This Row],[Date]]-SUMIFS(Games[Date],Games[Team],Games[[#This Row],[Opponent]],Games[Season],Games[[#This Row],[Season]],Games[Week],Games[[#This Row],[PrevWeekOpp]]))) | X9: =IF(Games[[#This Row],[Team]]="","",IF(OR(Games[[#This Row],[DaysOff]]="",Games[[#This Row],[OppDaysOff]]=""),0,IF(Games[[#This Row],[DaysOff]]-Games[[#This Row],[OppDaysOff]]=0,0,IF(ABS(Games[[#This Row],[DaysOff]]-Games[[#This Row],[OppDaysOff]])>=6,IF(Games[[#This Row],[DaysOff]]-Games[[#This Row],[OppDaysOff]]>0,RestMajor,-RestMajor),IF(Games[[#This Row],[DaysOff]]-Games[[#This Row],[OppDaysOff]]>0,RestMinor,-RestMinor))))) -> 0 | Y9: =IF(Games[[#This Row],[Team]]="","",IF(Games[[#This Row],[PrevWeekTeam]]>0,SUMIFS(Games[PostGmRate],Games[Team],Games[[#This Row],[Team]],Games[Season],Games[[#This Row],[Season]],Games[Week],Games[[#This Row],[PrevWeekTeam]]),Alpha*IFERROR(INDEX(Teams[PreseasonRating],MATCH(Games[[#This Row],[Team]],Teams[TeamID],0)),Base)+(1-Alpha)*Base)) -> 1500 | Z9: =IF(Games[[#This Row],[Team]]="","",IF(Games[[#This Row],[PrevWeekOpp]]>0,SUMIFS(Games[PostGmRate],Games[Team],Games[[#This Row],[Opponent]],Games[Season],Games[[#This Row],[Season]],Games[Week],Games[[#This Row],[PrevWeekOpp]]),Alpha*IFERROR(INDEX(Teams[PreseasonRating],MATCH(Games[[#This Row],[Opponent]],Teams[TeamID],0)),Base)+(1-Alpha)*Base)) -> 1500 | AA9: =IF(Games[[#This Row],[Team]]="","",1/(1+10^(((Games[[#This Row],[OppPreGmRate]]+IF(Games[[#This Row],[HomeAway]]="A",HFA-Games[[#This Row],[RestAdj]],0))-(Games[[#This Row],[PreGmRate]]+IF(Games[[#This Row],[HomeAway]]="H",HFA+Games[[#This Row],[RestAdj]],0)))/400))) -> 0.39784191 | AB9: =IF(Games[[#This Row],[Team]]="","",Games[[#This Row],[PointsFor]]-Games[[#This Row],[PointsAgainst]]) -> -4 | AC9: =IF(Games[[#This Row],[Team]]="","",IF(Games[[#This Row],[MOV]]>0,1,IF(Games[[#This Row],[MOV]]=0,0.5,0))) -> 0 | AD9: =IF(Games[[#This Row],[Team]]="","",--(OR(AND(Games[[#This Row],[ExpectedWin]]>=0.5,Games[[#This Row],[Result]]=1),AND(Games[[#This Row],[ExpectedWin]]<0.5,Games[[#This Row],[Result]]=0)))) -> 1 | AE9: =IF(Games[[#This Row],[Team]]="","",-(Games[[#This Row],[Result]]*LN(Games[[#This Row],[ExpectedWin]])+(1-Games[[#This Row],[Result]])*LN(1-Games[[#This Row],[ExpectedWin]]))) -> 0.50723525 | AF9: =IF(Games[[#This Row],[Team]]="","",IF(Games[[#This Row],[Season]]>=2021,17,16)) -> 16 | AG9: =IF(Games[[#This Row],[Team]]="","",KMax-(KMax-KFloor)*MIN(Games[[#This Row],[GamesPlayed]],Games[[#This Row],[SeasonLen]])/Games[[#This Row],[SeasonLen]]) -> 45.3875 | AH9: =IF(Games[[#This Row],[Team]]="","",((ABS(Games[[#This Row],[MOV]])+3)^0.8)/(7.5+0.006*ABS(Games[[#This Row],[PreGmRate]]-Games[[#This Row],[OppPreGmRate]]))*IF(Games[[#This Row],[OT]]=1,0.7,1)) -> 0.63243685 | AI9: =IF(Games[[#This Row],[Team]]="","",IF(Games[[#This Row],[Type]]="P",_xlfn.IFS(Games[[#This Row],[Round]]="WC",POMult_WC,Games[[#This Row],[Round]]="DV",POMult_DV,Games[[#This Row],[Round]]="CC",POMult_CC,Games[[#This Row],[Round]]="SB",POMult_SB,TRUE,1),1)) -> 1 | AJ9: =IF(Games[[#This Row],[Team]]="","",Games[[#This Row],[K]]*IF(Games[[#This Row],[DivG]]=1,DivMult,1)*IF(Games[[#This Row],[ConfG]]=1,ConfMult,1)*Games[[#This Row],[POMult]]) -> 50.924775 | AK9: =IF(Games[[#This Row],[Team]]="","",(Games[[#This Row],[Keff]]*Games[[#This Row],[MOVMult]])*(Games[[#This Row],[Result]]-Games[[#This Row],[ExpectedWin]])) -> -12.813177 | AL9: =IF(Games[[#This Row],[Team]]="","",Games[[#This Row],[PreGmRate]]+Games[[#This Row],[RatingChange]]) -> 1487.1868 | AM9: =IF(Games[[#This Row],[Team]]="","",IF(Games[[#This Row],[Type]]="R",IF(Games[[#This Row],[Result]]>0.5,1,0),0)) -> 0 | AN9: =IF(Games[[#This Row],[Team]]="","",IF(Games[[#This Row],[Type]]="R",IF(Games[[#This Row],[Result]]<0.5,1,0),0)) -> 1 | AO9: =IF(Games[[#This Row],[Team]]="","",IF(Games[[#This Row],[Type]]="R",IF(Games[[#This Row],[Result]]=0.5,1,0),0)) -> 0
