Workbook
Name alpha: RawData!$AP$3
Name base: RawData!$AP$4
Name HCA: RawData!$AP$2
Name HFA: RawData!$AP$2
Name k: RawData!#REF!
Name kmax: RawData!$AQ$1
Name kmin: RawData!$AP$1

Sheet DataTable
A1: TeamID | B1: Logo | C1: TeamName | D1: PreSeasonElo
A2: ATL | C2: Atlanta Dream | D2: 1397.7111
A3: CHI | C3: Chicago Sky | D3: 1405.7672
A4: CON | C4: Connecticut Sun | D4: 1547.5226
A5: DAL | C5: Dallas Wings | D5: 1444.7479
A6: IND | C6: Indiana Fever | D6: 1321.0528
A7: LVA | C7: Las Vegas Aces | D7: 1344.8247
A8: LAS | C8: Los Angeles Sparks | D8: 1705.9329
A9: MIN | C9: Minnesota Lynx | D9: 1744.3716
A10: NYL | C10: New York Liberty | D10: 1584.289
A11: PHX | C11: Phoenix Mercury | D11: 1532.0467
A12: SEA | C12: Seattle Storm | D12: 1471.7631
A13: WAS | C13: Washington Mystics | D13: 1500.6796

Sheet StandingsRaw
A2: {=_xlfn.SORTBY(A25:H36,G25:G36,-1)} -> SEA | B2: 0 | C2: Seattle Storm | D2: 26 | E2: 8 | F2: 0.76470588 | G2: 1698.3366 | H2: 43355 | AK2: HOU | AL2: =_xlfn.XLOOKUP(AK2,ConfDiv[TeamID],ConfDiv[Logo]) -> #N/A | AM2: =_xlfn.XLOOKUP(AK2,ConfDiv[TeamID],ConfDiv[TeamName]) -> #N/A | AN2: =_xlfn.XLOOKUP($AK2,StandingsPivot!$A$4:$A$33,StandingsPivot!D$4:D$33) -> #N/A | AO2: =_xlfn.XLOOKUP($AK2,StandingsPivot!$A$4:$A$33,StandingsPivot!E$4:E$33) -> #N/A | AP2: =_xlfn.XLOOKUP($AK2,StandingsPivot!$A$4:$A$33,StandingsPivot!F$4:F$33) -> #N/A | AQ2: =_xlfn.XLOOKUP($AK2,StandingsPivot!$A$4:$A$33,StandingsPivot!G$4:G$33) -> #N/A | AR2: =_xlfn.XLOOKUP($AK2,StandingsPivot!$A$4:$A$33,StandingsPivot!H$4:H$33) -> #N/A | AS2: =_xlfn.XLOOKUP($AK2,StandingsPivot!$A$4:$A$33,StandingsPivot!I$4:I$33) -> #N/A | AT2: =_xlfn.XLOOKUP($AK2,StandingsPivot!$A$4:$A$33,StandingsPivot!J$4:J$33) -> #N/A | AU2: =_xlfn.XLOOKUP($AK2,StandingsPivot!$A$4:$A$33,StandingsPivot!K$4:K$33) -> #N/A | AV2: =SUM(AN2,AP2,AR2,AT2) -> #N/A | AW2: =SUM(AO2,AQ2,AS2,AU2) -> #N/A | AX2: {=_xlfn.IFNA(INDEX(Games[PostGmRate], MATCH(1, (Games[Team]=AK2)*(Games[Date]=AY2), 0)),0)} -> 0 | AY2: =_xlfn.MAXIFS(Games[Date], Games[Team], AK2) -> 0 | AZ2: =SUM(AV2:AW2) -> #N/A
A3: CON | B3: 0 | C3: Connecticut Sun | D3: 21 | E3: 13 | F3: 0.61764706 | G3: 1587.573 | H3: 43335 | AK3: NYL | AL3: =_xlfn.XLOOKUP(AK3,ConfDiv[TeamID],ConfDiv[Logo]) -> 0 | AM3: =_xlfn.XLOOKUP(AK3,ConfDiv[TeamID],ConfDiv[TeamName]) -> New York Liberty | AN3: =_xlfn.XLOOKUP($AK3,StandingsPivot!$A$4:$A$33,StandingsPivot!D$4:D$33) -> 0 | AO3: =_xlfn.XLOOKUP($AK3,StandingsPivot!$A$4:$A$33,StandingsPivot!E$4:E$33) -> 0 | AP3: =_xlfn.XLOOKUP($AK3,StandingsPivot!$A$4:$A$33,StandingsPivot!F$4:F$33) -> 0 | AQ3: =_xlfn.XLOOKUP($AK3,StandingsPivot!$A$4:$A$33,StandingsPivot!G$4:G$33) -> 0 | AR3: =_xlfn.XLOOKUP($AK3,StandingsPivot!$A$4:$A$33,StandingsPivot!H$4:H$33) -> 0 | AS3: =_xlfn.XLOOKUP($AK3,StandingsPivot!$A$4:$A$33,StandingsPivot!I$4:I$33) -> 0 | AT3: =_xlfn.XLOOKUP($AK3,StandingsPivot!$A$4:$A$33,StandingsPivot!J$4:J$33) -> 0 | AU3: =_xlfn.XLOOKUP($AK3,StandingsPivot!$A$4:$A$33,StandingsPivot!K$4:K$33) -> 0 | AV3: =SUM(AN3,AP3,AR3,AT3) -> 0 | AW3: =SUM(AO3,AQ3,AS3,AU3) -> 0 | AX3: {=_xlfn.IFNA(INDEX(Games[PostGmRate], MATCH(1, (Games[Team]=AK3)*(Games[Date]=AY3), 0)),0)} -> 1326.7492 | AY3: =_xlfn.MAXIFS(Games[Date], Games[Team], AK3) -> 43331 | AZ3: =SUM(AV3:AW3) -> 0
A4: PHX | B4: 0 | C4: Phoenix Mercury | D4: 20 | E4: 14 | F4: 0.58823529 | G4: 1583.9487 | H4: 43347 | AK4: CHA | AL4: =_xlfn.XLOOKUP(AK4,ConfDiv[TeamID],ConfDiv[Logo]) -> #N/A | AM4: =_xlfn.XLOOKUP(AK4,ConfDiv[TeamID],ConfDiv[TeamName]) -> #N/A | AN4: =_xlfn.XLOOKUP($AK4,StandingsPivot!$A$4:$A$33,StandingsPivot!D$4:D$33) -> #N/A | AO4: =_xlfn.XLOOKUP($AK4,StandingsPivot!$A$4:$A$33,StandingsPivot!E$4:E$33) -> #N/A | AP4: =_xlfn.XLOOKUP($AK4,StandingsPivot!$A$4:$A$33,StandingsPivot!F$4:F$33) -> #N/A | AQ4: =_xlfn.XLOOKUP($AK4,StandingsPivot!$A$4:$A$33,StandingsPivot!G$4:G$33) -> #N/A | AR4: =_xlfn.XLOOKUP($AK4,StandingsPivot!$A$4:$A$33,StandingsPivot!H$4:H$33) -> #N/A | AS4: =_xlfn.XLOOKUP($AK4,StandingsPivot!$A$4:$A$33,StandingsPivot!I$4:I$33) -> #N/A | AT4: =_xlfn.XLOOKUP($AK4,StandingsPivot!$A$4:$A$33,StandingsPivot!J$4:J$33) -> #N/A | AU4: =_xlfn.XLOOKUP($AK4,StandingsPivot!$A$4:$A$33,StandingsPivot!K$4:K$33) -> #N/A | AV4: =SUM(AN4,AP4,AR4,AT4) -> #N/A | AW4: =SUM(AO4,AQ4,AS4,AU4) -> #N/A | AX4: {=_xlfn.IFNA(INDEX(Games[PostGmRate], MATCH(1, (Games[Team]=AK4)*(Games[Date]=AY4), 0)),0)} -> 0 | AY4: =_xlfn.MAXIFS(Games[Date], Games[Team], AK4) -> 0 | AZ4: =SUM(AV4:AW4) -> #N/A
A5: WAS | B5: 0 | C5: Washington Mystics | D5: 22 | E5: 12 | F5: 0.64705882 | G5: 1581.1587 | H5: 43355 | AK5: CLE | AL5: =_xlfn.XLOOKUP(AK5,ConfDiv[TeamID],ConfDiv[Logo]) -> #N/A | AM5: =_xlfn.XLOOKUP(AK5,ConfDiv[TeamID],ConfDiv[TeamName]) -> #N/A | AN5: =_xlfn.XLOOKUP($AK5,StandingsPivot!$A$4:$A$33,StandingsPivot!D$4:D$33) -> #N/A | AO5: =_xlfn.XLOOKUP($AK5,StandingsPivot!$A$4:$A$33,StandingsPivot!E$4:E$33) -> #N/A | AP5: =_xlfn.XLOOKUP($AK5,StandingsPivot!$A$4:$A$33,StandingsPivot!F$4:F$33) -> #N/A | AQ5: =_xlfn.XLOOKUP($AK5,StandingsPivot!$A$4:$A$33,StandingsPivot!G$4:G$33) -> #N/A | AR5: =_xlfn.XLOOKUP($AK5,StandingsPivot!$A$4:$A$33,StandingsPivot!H$4:H$33) -> #N/A | AS5: =_xlfn.XLOOKUP($AK5,StandingsPivot!$A$4:$A$33,StandingsPivot!I$4:I$33) -> #N/A | AT5: =_xlfn.XLOOKUP($AK5,StandingsPivot!$A$4:$A$33,StandingsPivot!J$4:J$33) -> #N/A | AU5: =_xlfn.XLOOKUP($AK5,StandingsPivot!$A$4:$A$33,StandingsPivot!K$4:K$33) -> #N/A | AV5: =SUM(AN5,AP5,AR5,AT5) -> #N/A | AW5: =SUM(AO5,AQ5,AS5,AU5) -> #N/A | AX5: {=_xlfn.IFNA(INDEX(Games[PostGmRate], MATCH(1, (Games[Team]=AK5)*(Games[Date]=AY5), 0)),0)} -> 0 | AY5: =_xlfn.MAXIFS(Games[Date], Games[Team], AK5) -> 0 | AZ5: =SUM(AV5:AW5) -> #N/A
A6: ATL | B6: 0 | C6: Atlanta Dream | D6: 23 | E6: 11 | F6: 0.67647059 | G6: 1568.0595 | H6: 43347 | AK6: PHX | AL6: =_xlfn.XLOOKUP(AK6,ConfDiv[TeamID],ConfDiv[Logo]) -> 0 | AM6: =_xlfn.XLOOKUP(AK6,ConfDiv[TeamID],ConfDiv[TeamName]) -> Phoenix Mercury | AN6: =_xlfn.XLOOKUP($AK6,StandingsPivot!$A$4:$A$33,StandingsPivot!D$4:D$33) -> 1 | AO6: =_xlfn.XLOOKUP($AK6,StandingsPivot!$A$4:$A$33,StandingsPivot!E$4:E$33) -> 0 | AP6: =_xlfn.XLOOKUP($AK6,StandingsPivot!$A$4:$A$33,StandingsPivot!F$4:F$33) -> 2 | AQ6: =_xlfn.XLOOKUP($AK6,StandingsPivot!$A$4:$A$33,StandingsPivot!G$4:G$33) -> 3 | AR6: =_xlfn.XLOOKUP($AK6,StandingsPivot!$A$4:$A$33,StandingsPivot!H$4:H$33) -> 0 | AS6: =_xlfn.XLOOKUP($AK6,StandingsPivot!$A$4:$A$33,StandingsPivot!I$4:I$33) -> 0 | AT6: =_xlfn.XLOOKUP($AK6,StandingsPivot!$A$4:$A$33,StandingsPivot!J$4:J$33) -> 0 | AU6: =_xlfn.XLOOKUP($AK6,StandingsPivot!$A$4:$A$33,StandingsPivot!K$4:K$33) -> 0 | AV6: =SUM(AN6,AP6,AR6,AT6) -> 3 | AW6: =SUM(AO6,AQ6,AS6,AU6) -> 3 | AX6: {=_xlfn.IFNA(INDEX(Games[PostGmRate], MATCH(1, (Games[Team]=AK6)*(Games[Date]=AY6), 0)),0)} -> 1583.9487 | AY6: =_xlfn.MAXIFS(Games[Date], Games[Team], AK6) -> 43347 | AZ6: =SUM(AV6:AW6) -> 6
A7: LAS | B7: 0 | C7: Los Angeles Sparks | D7: 19 | E7: 15 | F7: 0.55882353 | G7: 1535.9881 | H7: 43335 | AK7: LAS | AL7: =_xlfn.XLOOKUP(AK7,ConfDiv[TeamID],ConfDiv[Logo]) -> 0 | AM7: =_xlfn.XLOOKUP(AK7,ConfDiv[TeamID],ConfDiv[TeamName]) -> Los Angeles Sparks | AN7: =_xlfn.XLOOKUP($AK7,StandingsPivot!$A$4:$A$33,StandingsPivot!D$4:D$33) -> 0 | AO7: =_xlfn.XLOOKUP($AK7,StandingsPivot!$A$4:$A$33,StandingsPivot!E$4:E$33) -> 1 | AP7: =_xlfn.XLOOKUP($AK7,StandingsPivot!$A$4:$A$33,StandingsPivot!F$4:F$33) -> 0 | AQ7: =_xlfn.XLOOKUP($AK7,StandingsPivot!$A$4:$A$33,StandingsPivot!G$4:G$33) -> 0 | AR7: =_xlfn.XLOOKUP($AK7,StandingsPivot!$A$4:$A$33,StandingsPivot!H$4:H$33) -> 0 | AS7: =_xlfn.XLOOKUP($AK7,StandingsPivot!$A$4:$A$33,StandingsPivot!I$4:I$33) -> 0 | AT7: =_xlfn.XLOOKUP($AK7,StandingsPivot!$A$4:$A$33,StandingsPivot!J$4:J$33) -> 0 | AU7: =_xlfn.XLOOKUP($AK7,StandingsPivot!$A$4:$A$33,StandingsPivot!K$4:K$33) -> 0 | AV7: =SUM(AN7,AP7,AR7,AT7) -> 0 | AW7: =SUM(AO7,AQ7,AS7,AU7) -> 1 | AX7: {=_xlfn.IFNA(INDEX(Games[PostGmRate], MATCH(1, (Games[Team]=AK7)*(Games[Date]=AY7), 0)),0)} -> 1535.9881 | AY7: =_xlfn.MAXIFS(Games[Date], Games[Team], AK7) -> 43335 | AZ7: =SUM(AV7:AW7) -> 1
A8: MIN | B8: 0 | C8: Minnesota Lynx | D8: 18 | E8: 16 | F8: 0.52941176 | G8: 1534.0253 | H8: 43333 | AK8: SAC | AL8: =_xlfn.XLOOKUP(AK8,ConfDiv[TeamID],ConfDiv[Logo]) -> #N/A | AM8: =_xlfn.XLOOKUP(AK8,ConfDiv[TeamID],ConfDiv[TeamName]) -> #N/A | AN8: =_xlfn.XLOOKUP($AK8,StandingsPivot!$A$4:$A$33,StandingsPivot!D$4:D$33) -> #N/A | AO8: =_xlfn.XLOOKUP($AK8,StandingsPivot!$A$4:$A$33,StandingsPivot!E$4:E$33) -> #N/A | AP8: =_xlfn.XLOOKUP($AK8,StandingsPivot!$A$4:$A$33,StandingsPivot!F$4:F$33) -> #N/A | AQ8: =_xlfn.XLOOKUP($AK8,StandingsPivot!$A$4:$A$33,StandingsPivot!G$4:G$33) -> #N/A | AR8: =_xlfn.XLOOKUP($AK8,StandingsPivot!$A$4:$A$33,StandingsPivot!H$4:H$33) -> #N/A | AS8: =_xlfn.XLOOKUP($AK8,StandingsPivot!$A$4:$A$33,StandingsPivot!I$4:I$33) -> #N/A | AT8: =_xlfn.XLOOKUP($AK8,StandingsPivot!$A$4:$A$33,StandingsPivot!J$4:J$33) -> #N/A | AU8: =_xlfn.XLOOKUP($AK8,StandingsPivot!$A$4:$A$33,StandingsPivot!K$4:K$33) -> #N/A | AV8: =SUM(AN8,AP8,AR8,AT8) -> #N/A | AW8: =SUM(AO8,AQ8,AS8,AU8) -> #N/A | AX8: {=_xlfn.IFNA(INDEX(Games[PostGmRate], MATCH(1, (Games[Team]=AK8)*(Games[Date]=AY8), 0)),0)} -> 0 | AY8: =_xlfn.MAXIFS(Games[Date], Games[Team], AK8) -> 0 | AZ8: =SUM(AV8:AW8) -> #N/A
A9: DAL | B9: 0 | C9: Dallas Wings | D9: 15 | E9: 19 | F9: 0.44117647 | G9: 1451.5296 | H9: 43333 | AK9: UTA | AL9: =_xlfn.XLOOKUP(AK9,ConfDiv[TeamID],ConfDiv[Logo]) -> #N/A | AM9: =_xlfn.XLOOKUP(AK9,ConfDiv[TeamID],ConfDiv[TeamName]) -> #N/A | AN9: =_xlfn.XLOOKUP($AK9,StandingsPivot!$A$4:$A$33,StandingsPivot!D$4:D$33) -> #N/A | AO9: =_xlfn.XLOOKUP($AK9,StandingsPivot!$A$4:$A$33,StandingsPivot!E$4:E$33) -> #N/A | AP9: =_xlfn.XLOOKUP($AK9,StandingsPivot!$A$4:$A$33,StandingsPivot!F$4:F$33) -> #N/A | AQ9: =_xlfn.XLOOKUP($AK9,StandingsPivot!$A$4:$A$33,StandingsPivot!G$4:G$33) -> #N/A | AR9: =_xlfn.XLOOKUP($AK9,StandingsPivot!$A$4:$A$33,StandingsPivot!H$4:H$33) -> #N/A | AS9: =_xlfn.XLOOKUP($AK9,StandingsPivot!$A$4:$A$33,StandingsPivot!I$4:I$33) -> #N/A | AT9: =_xlfn.XLOOKUP($AK9,StandingsPivot!$A$4:$A$33,StandingsPivot!J$4:J$33) -> #N/A | AU9: =_xlfn.XLOOKUP($AK9,StandingsPivot!$A$4:$A$33,StandingsPivot!K$4:K$33) -> #N/A | AV9: =SUM(AN9,AP9,AR9,AT9) -> #N/A | AW9: =SUM(AO9,AQ9,AS9,AU9) -> #N/A | AX9: {=_xlfn.IFNA(INDEX(Games[PostGmRate], MATCH(1, (Games[Team]=AK9)*(Games[Date]=AY9), 0)),0)} -> 0 | AY9: =_xlfn.MAXIFS(Games[Date], Games[Team], AK9) -> 0 | AZ9: =SUM(AV9:AW9) -> #N/A
A10: LVA | B10: 0 | C10: Las Vegas Aces | D10: 14 | E10: 20 | F10: 0.41176471 | G10: 1423.7957 | H10: 43331
A11: CHI | B11: 0 | C11: Chicago Sky | D11: 13 | E11: 21 | F11: 0.38235294 | G11: 1401.1928 | H11: 43331
A12: NYL | B12: 0 | C12: New York Liberty | D12: 7 | E12: 27 | F12: 0.20588235 | G12: 1326.7492 | H12: 43331
A13: IND | B13: 0 | C13: Indiana Fever | D13: 6 | E13: 28 | F13: 0.17647059 | G13: 1307.7517 | H13: 43331
A25: ATL | B25: =_xlfn.XLOOKUP(A25,ConfDiv[TeamID],ConfDiv[Logo]) -> 0 | C25: =_xlfn.XLOOKUP(A25,ConfDiv[TeamID],ConfDiv[TeamName]) -> Atlanta Dream | D25: =_xlfn.XLOOKUP($A25,StandingsPivot!$A$4:$A$35,StandingsPivot!B$4:B$35) -> 23 | E25: =_xlfn.XLOOKUP($A25,StandingsPivot!$A$4:$A$35,StandingsPivot!C$4:C$35) -> 11 | F25: =(D25)/(D25+E25) -> 0.67647059 | G25: {=INDEX(Games[PostGmRate], MATCH(1, (Games[Team]=A25)*(Games[Date]=H25), 0))} -> 1568.0595 | H25: =_xlfn.MAXIFS(Games[Date], Games[Team], A25) -> 43347
A26: CHI | B26: =_xlfn.XLOOKUP(A26,ConfDiv[TeamID],ConfDiv[Logo]) -> 0 | C26: =_xlfn.XLOOKUP(A26,ConfDiv[TeamID],ConfDiv[TeamName]) -> Chicago Sky | D26: =_xlfn.XLOOKUP($A26,StandingsPivot!$A$4:$A$35,StandingsPivot!B$4:B$35) -> 13 | E26: =_xlfn.XLOOKUP($A26,StandingsPivot!$A$4:$A$35,StandingsPivot!C$4:C$35) -> 21 | F26: =(D26)/(D26+E26) -> 0.38235294 | G26: {=INDEX(Games[PostGmRate], MATCH(1, (Games[Team]=A26)*(Games[Date]=H26), 0))} -> 1401.1928 | H26: =_xlfn.MAXIFS(Games[Date], Games[Team], A26) -> 43331
A27: CON | B27: =_xlfn.XLOOKUP(A27,ConfDiv[TeamID],ConfDiv[Logo]) -> 0 | C27: =_xlfn.XLOOKUP(A27,ConfDiv[TeamID],ConfDiv[TeamName]) -> Connecticut Sun | D27: =_xlfn.XLOOKUP($A27,StandingsPivot!$A$4:$A$35,StandingsPivot!B$4:B$35) -> 21 | E27: =_xlfn.XLOOKUP($A27,StandingsPivot!$A$4:$A$35,StandingsPivot!C$4:C$35) -> 13 | F27: =(D27)/(D27+E27) -> 0.61764706 | G27: {=INDEX(Games[PostGmRate], MATCH(1, (Games[Team]=A27)*(Games[Date]=H27), 0))} -> 1587.573 | H27: =_xlfn.MAXIFS(Games[Date], Games[Team], A27) -> 43335
A28: DAL | B28: =_xlfn.XLOOKUP(A28,ConfDiv[TeamID],ConfDiv[Logo]) -> 0 | C28: =_xlfn.XLOOKUP(A28,ConfDiv[TeamID],ConfDiv[TeamName]) -> Dallas Wings | D28: =_xlfn.XLOOKUP($A28,StandingsPivot!$A$4:$A$35,StandingsPivot!B$4:B$35) -> 15 | E28: =_xlfn.XLOOKUP($A28,StandingsPivot!$A$4:$A$35,StandingsPivot!C$4:C$35) -> 19 | F28: =(D28)/(D28+E28) -> 0.44117647 | G28: {=INDEX(Games[PostGmRate], MATCH(1, (Games[Team]=A28)*(Games[Date]=H28), 0))} -> 1451.5296 | H28: =_xlfn.MAXIFS(Games[Date], Games[Team], A28) -> 43333
A29: IND | B29: =_xlfn.XLOOKUP(A29,ConfDiv[TeamID],ConfDiv[Logo]) -> 0 | C29: =_xlfn.XLOOKUP(A29,ConfDiv[TeamID],ConfDiv[TeamName]) -> Indiana Fever | D29: =_xlfn.XLOOKUP($A29,StandingsPivot!$A$4:$A$35,StandingsPivot!B$4:B$35) -> 6 | E29: =_xlfn.XLOOKUP($A29,StandingsPivot!$A$4:$A$35,StandingsPivot!C$4:C$35) -> 28 | F29: =(D29)/(D29+E29) -> 0.17647059 | G29: {=INDEX(Games[PostGmRate], MATCH(1, (Games[Team]=A29)*(Games[Date]=H29), 0))} -> 1307.7517 | H29: =_xlfn.MAXIFS(Games[Date], Games[Team], A29) -> 43331
A30: LAS | B30: =_xlfn.XLOOKUP(A30,ConfDiv[TeamID],ConfDiv[Logo]) -> 0 | C30: =_xlfn.XLOOKUP(A30,ConfDiv[TeamID],ConfDiv[TeamName]) -> Los Angeles Sparks | D30: =_xlfn.XLOOKUP($A30,StandingsPivot!$A$4:$A$35,StandingsPivot!B$4:B$35) -> 19 | E30: =_xlfn.XLOOKUP($A30,StandingsPivot!$A$4:$A$35,StandingsPivot!C$4:C$35) -> 15 | F30: =(D30)/(D30+E30) -> 0.55882353 | G30: {=INDEX(Games[PostGmRate], MATCH(1, (Games[Team]=A30)*(Games[Date]=H30), 0))} -> 1535.9881 | H30: =_xlfn.MAXIFS(Games[Date], Games[Team], A30) -> 43335
A31: LVA | B31: =_xlfn.XLOOKUP(A31,ConfDiv[TeamID],ConfDiv[Logo]) -> 0 | C31: =_xlfn.XLOOKUP(A31,ConfDiv[TeamID],ConfDiv[TeamName]) -> Las Vegas Aces | D31: =_xlfn.XLOOKUP($A31,StandingsPivot!$A$4:$A$35,StandingsPivot!B$4:B$35) -> 14 | E31: =_xlfn.XLOOKUP($A31,StandingsPivot!$A$4:$A$35,StandingsPivot!C$4:C$35) -> 20 | F31: =(D31)/(D31+E31) -> 0.41176471 | G31: {=INDEX(Games[PostGmRate], MATCH(1, (Games[Team]=A31)*(Games[Date]=H31), 0))} -> 1423.7957 | H31: =_xlfn.MAXIFS(Games[Date], Games[Team], A31) -> 43331
A32: MIN | B32: =_xlfn.XLOOKUP(A32,ConfDiv[TeamID],ConfDiv[Logo]) -> 0 | C32: =_xlfn.XLOOKUP(A32,ConfDiv[TeamID],ConfDiv[TeamName]) -> Minnesota Lynx | D32: =_xlfn.XLOOKUP($A32,StandingsPivot!$A$4:$A$35,StandingsPivot!B$4:B$35) -> 18 | E32: =_xlfn.XLOOKUP($A32,StandingsPivot!$A$4:$A$35,StandingsPivot!C$4:C$35) -> 16 | F32: =(D32)/(D32+E32) -> 0.52941176 | G32: {=INDEX(Games[PostGmRate], MATCH(1, (Games[Team]=A32)*(Games[Date]=H32), 0))} -> 1534.0253 | H32: =_xlfn.MAXIFS(Games[Date], Games[Team], A32) -> 43333
A33: NYL | B33: =_xlfn.XLOOKUP(A33,ConfDiv[TeamID],ConfDiv[Logo]) -> 0 | C33: =_xlfn.XLOOKUP(A33,ConfDiv[TeamID],ConfDiv[TeamName]) -> New York Liberty | D33: =_xlfn.XLOOKUP($A33,StandingsPivot!$A$4:$A$35,StandingsPivot!B$4:B$35) -> 7 | E33: =_xlfn.XLOOKUP($A33,StandingsPivot!$A$4:$A$35,StandingsPivot!C$4:C$35) -> 27 | F33: =(D33)/(D33+E33) -> 0.20588235 | G33: {=INDEX(Games[PostGmRate], MATCH(1, (Games[Team]=A33)*(Games[Date]=H33), 0))} -> 1326.7492 | H33: =_xlfn.MAXIFS(Games[Date], Games[Team], A33) -> 43331
A34: PHX | B34: =_xlfn.XLOOKUP(A34,ConfDiv[TeamID],ConfDiv[Logo]) -> 0 | C34: =_xlfn.XLOOKUP(A34,ConfDiv[TeamID],ConfDiv[TeamName]) -> Phoenix Mercury | D34: =_xlfn.XLOOKUP($A34,StandingsPivot!$A$4:$A$35,StandingsPivot!B$4:B$35) -> 20 | E34: =_xlfn.XLOOKUP($A34,StandingsPivot!$A$4:$A$35,StandingsPivot!C$4:C$35) -> 14 | F34: =(D34)/(D34+E34) -> 0.58823529 | G34: {=INDEX(Games[PostGmRate], MATCH(1, (Games[Team]=A34)*(Games[Date]=H34), 0))} -> 1583.9487 | H34: =_xlfn.MAXIFS(Games[Date], Games[Team], A34) -> 43347
A35: SEA | B35: =_xlfn.XLOOKUP(A35,ConfDiv[TeamID],ConfDiv[Logo]) -> 0 | C35: =_xlfn.XLOOKUP(A35,ConfDiv[TeamID],ConfDiv[TeamName]) -> Seattle Storm | D35: =_xlfn.XLOOKUP($A35,StandingsPivot!$A$4:$A$35,StandingsPivot!B$4:B$35) -> 26 | E35: =_xlfn.XLOOKUP($A35,StandingsPivot!$A$4:$A$35,StandingsPivot!C$4:C$35) -> 8 | F35: =(D35)/(D35+E35) -> 0.76470588 | G35: {=INDEX(Games[PostGmRate], MATCH(1, (Games[Team]=A35)*(Games[Date]=H35), 0))} -> 1698.3366 | H35: =_xlfn.MAXIFS(Games[Date], Games[Team], A35) -> 43355
A36: WAS | B36: =_xlfn.XLOOKUP(A36,ConfDiv[TeamID],ConfDiv[Logo]) -> 0 | C36: =_xlfn.XLOOKUP(A36,ConfDiv[TeamID],ConfDiv[TeamName]) -> Washington Mystics | D36: =_xlfn.XLOOKUP($A36,StandingsPivot!$A$4:$A$35,StandingsPivot!B$4:B$35) -> 22 | E36: =_xlfn.XLOOKUP($A36,StandingsPivot!$A$4:$A$35,StandingsPivot!C$4:C$35) -> 12 | F36: =(D36)/(D36+E36) -> 0.64705882 | G36: {=INDEX(Games[PostGmRate], MATCH(1, (Games[Team]=A36)*(Games[Date]=H36), 0))} -> 1581.1587 | H36: =_xlfn.MAXIFS(Games[Date], Games[Team], A36) -> 43355

Sheet StandingsPivot
A3: Row Labels | B3: Sum of W | C3: Sum of L | D3: Sum of R1W | E3: Sum of R1L | F3: Sum of R2W | G3: Sum of R2L | H3: Sum of R3W | I3: Sum of R3L | J3: Sum of FW | K3: Sum of FL
A4: ATL | B4: 23 | C4: 11 | D4: 0 | E4: 0 | F4: 2 | G4: 3 | H4: 0 | I4: 0 | J4: 0 | K4: 0
A5: CHI | B5: 13 | C5: 21 | D5: 0 | E5: 0 | F5: 0 | G5: 0 | H5: 0 | I5: 0 | J5: 0 | K5: 0
A6: CON | B6: 21 | C6: 13 | D6: 0 | E6: 1 | F6: 0 | G6: 0 | H6: 0 | I6: 0 | J6: 0 | K6: 0
A7: DAL | B7: 15 | C7: 19 | D7: 0 | E7: 0 | F7: 0 | G7: 0 | H7: 0 | I7: 0 | J7: 0 | K7: 0
A8: IND | B8: 6 | C8: 28 | D8: 0 | E8: 0 | F8: 0 | G8: 0 | H8: 0 | I8: 0 | J8: 0 | K8: 0
A9: LAS | B9: 19 | C9: 15 | D9: 0 | E9: 1 | F9: 0 | G9: 0 | H9: 0 | I9: 0 | J9: 0 | K9: 0
A10: LVA | B10: 14 | C10: 20 | D10: 0 | E10: 0 | F10: 0 | G10: 0 | H10: 0 | I10: 0 | J10: 0 | K10: 0
A11: MIN | B11: 18 | C11: 16 | D11: 0 | E11: 0 | F11: 0 | G11: 0 | H11: 0 | I11: 0 | J11: 0 | K11: 0
A12: NYL | B12: 7 | C12: 27 | D12: 0 | E12: 0 | F12: 0 | G12: 0 | H12: 0 | I12: 0 | J12: 0 | K12: 0
A13: PHX | B13: 20 | C13: 14 | D13: 1 | E13: 0 | F13: 2 | G13: 3 | H13: 0 | I13: 0 | J13: 0 | K13: 0
A14: SEA | B14: 26 | C14: 8 | D14: 0 | E14: 0 | F14: 3 | G14: 2 | H14: 3 | I14: 0 | J14: 0 | K14: 0
A15: WAS | B15: 22 | C15: 12 | D15: 1 | E15: 0 | F15: 3 | G15: 2 | H15: 0 | I15: 3 | J15: 0 | K15: 0
A16: Grand Total | B16: 204 | C16: 204 | D16: 2 | E16: 2 | F16: 10 | G16: 10 | H16: 3 | I16: 3 | J16: 0 | K16: 0

Sheet Sheet1
A3: Row Labels
A4: 1
A5: 2
A6: 3
A7: 4
A8: 5
A9: 6
A10: 7
A11: 8
A12: 9
A13: 10
A14: 11
A15: 12
... A46: 43
A47: Grand Total

Sheet RawData
A1: Date | B1: Season | C1: GamesPlayed | D1: Type | E1: Round | F1: Team | G1: Opponent | H1: HomeAway | I1: DaysOff | J1: OppDaysOff | K1: RestDiff | L1: OppRestDiff | M1: RestAdj | N1: OppRestAdj | O1: PreGmRate | P1: OppPreGmRate | Q1: ExpectedWin% | R1: PointsFor | S1: PointsAgainst | T1: OT | U1: MOV | V1: Result | W1: MOVMult | X1: POMult | Y1: K | Z1: Keff | AA1: RatingChange | AB1: PostGmRate | AC1: W | AD1: L | AE1: R1W | AF1: R1L | AG1: R2W | AH1: R2L | AI1: R3W | AJ1: R3L | AK1: FW | AL1: FL | AP1: 6 | AQ1: 76
A2: 43238 | B2: 2018 | C2: =COUNTIFS(Games[Team],Games[[#This Row],[Team]],Games[Season],Games[[#This Row],[Season]],Games[Date],"<=" & Games[[#This Row],[Date]]) -> 1 | D2: R | E2: RS | F2: DAL | G2: PHX | H2: A | I2: {=IFERROR( Games[[#This Row],[Date]] - LOOKUP( 2, 1/((Games[Team]=Games[[#This Row],[Team]]) * (Games[Date] < Games[[#This Row],[Date]])), Games[Date] ) - 1, Games[[#This Row],[Date]]-$A$2)} -> 0 | J2: {=IFERROR( Games[[#This Row],[Date]] - LOOKUP( 2, 1/((Games[Opponent]=Games[[#This Row],[Opponent]]) * (Games[Date] < Games[[#This Row],[Date]])), Games[Date] ) - 1, Games[[#This Row],[Date]]-$A$2)} -> 0 | K2: =Games[[#This Row],[DaysOff]]-Games[[#This Row],[OppDaysOff]] -> 0 | L2: =Games[[#This Row],[OppDaysOff]]-Games[[#This Row],[DaysOff]] -> 0 | M2: =MAX(-16, MIN(16, Games[[#This Row],[RestDiff]]*8)) -> 0 | N2: =MAX(-16, MIN(16, Games[[#This Row],[OppRestDiff]]*8)) -> 0 | O2: {=IFERROR( LOOKUP( 2, 1/((Games[Team]=Games[[#This Row],[Team]]) * (Games[Season]=Games[[#This Row],[Season]]) * (Games[Date] < Games[[#This Row],[Date]])), Games[PostGmRate] ), IFERROR( alpha * _xlfn.XLOOKUP(Games[[#This Row],[Team]], ConfDiv[TeamID], ConfDiv[PreSeasonElo], base) + (1 - alpha) * base, base ) )} -> 1472.3739 | P2: {=IFERROR( LOOKUP( 2, 1/((Games[Team]=Games[[#This Row],[Opponent]]) * (Games[Season]=Games[[#This Row],[Season]]) * (Games[Date] < Games[[#This Row],[Date]])), Games[PostGmRate] ), IFERROR( alpha * _xlfn.XLOOKUP(Games[[#This Row],[Opponent]], ConfDiv[TeamID], ConfDiv[PreSeasonElo], base) + (1 - alpha) * base, base ) )} -> 1516.0233 | Q2: =1/(1+10^(((Games[[#This Row],[OppPreGmRate]]+IF(Games[[#This Row],[HomeAway]]="A",HCA,0)+Games[[#This Row],[OppRestAdj]])-(Games[[#This Row],[PreGmRate]]+IF(Games[[#This Row],[HomeAway]]="H",HCA,0)+Games[[#This Row],[RestAdj]]))/400)) -> 0.32414028 | R2: 78 | S2: 86 | T2: 0 | U2: =Games[[#This Row],[PointsFor]]-Games[[#This Row],[PointsAgainst]] -> -8 | V2: =IF(Games[[#This Row],[MOV]]>0,1,IF(Games[[#This Row],[MOV]]=0,0.5,0)) -> 0 | W2: =((ABS(Games[[#This Row],[MOV]])+5)^0.6)/(12+0.01*(ABS(Games[[#This Row],[PreGmRate]]-Games[[#This Row],[OppPreGmRate]])))*IF(Games[[#This Row],[OT]]=1,0.9,1) -> 0.37468649 | X2: {=IF(Games[[#This Row],[Type]]="P", _xlfn.IFS( Games[[#This Row],[Round]]=1,1.1, Games[[#This Row],[Round]]=2,1.2, Games[[#This Row],[Round]]=3,1.35, Games[[#This Row],[Round]]=4,1.5,Games[[#This Row],[Round]]=0.5,1.05, TRUE,1 ), 1)} -> 1 | Y2: =MAX(kmin, kmax - 0.15 * MIN(Games[[#This Row],[GamesPlayed]], 82)) -> 75.85 | Z2: =Games[[#This Row],[K]]*Games[[#This Row],[POMult]] -> 75.85 | AA2: =(Games[[#This Row],[Keff]]*Games[[#This Row],[MOVMult]])*(Games[[#This Row],[Result]]-Games[[#This Row],[ExpectedWin%]]) -> -9.2120574 | AB2: =Games[[#This Row],[PreGmRate]]+Games[[#This Row],[RatingChange]] -> 1463.1619 | AC2: =IF(Games[[#This Row],[Type]]="R",IF(Games[[#This Row],[Result]]>0.5,1,0),0) -> 0 | AD2: =IF(Games[[#This Row],[Type]]="R",IF(Games[[#This Row],[Result]]<0.5,1,0),0) -> 1 | AE2: =IF(AND(Games[[#This Row],[Type]]="P",Games[[#This Row],[Round]]=1),IF(Games[[#This Row],[Result]]>0.5,1,0),0) -> 0 | AF2: =IF(AND(Games[[#This Row],[Type]]="P",Games[[#This Row],[Round]]=1),IF(Games[[#This Row],[Result]]<0.5,1,0),0) -> 0 | AG2: =IF(AND(Games[[#This Row],[Type]]="P",Games[[#This Row],[Round]]=2),IF(Games[[#This Row],[Result]]>0.5,1,0),0) -> 0 | AH2: =IF(AND(Games[[#This Row],[Type]]="P",Games[[#This Row],[Round]]=2),IF(Games[[#This Row],[Result]]<0.5,1,0),0) -> 0 | AI2: =IF(AND(Games[[#This Row],[Type]]="P",Games[[#This Row],[Round]]=3),IF(Games[[#This Row],[Result]]>0.5,1,0),0) -> 0 | AJ2: =IF(AND(Games[[#This Row],[Type]]="P",Games[[#This Row],[Round]]=3),IF(Games[[#This Row],[Result]]<0.5,1,0),0) -> 0 | AK2: =IF(AND(Games[[#This Row],[Type]]="P",Games[[#This Row],[Round]]=4),IF(Games[[#This Row],[Result]]>0.5,1,0),0) -> 0 | AL2: =IF(AND(Games[[#This Row],[Type]]="P",Games[[#This Row],[Round]]=4),IF(Games[[#This Row],[Result]]<0.5,1,0),0) -> 0 | AP2: 84
A3: 43238 | B3: 2018 | C3: =COUNTIFS(Games[Team],Games[[#This Row],[Team]],Games[Season],Games[[#This Row],[Season]],Games[Date],"<=" & Games[[#This Row],[Date]]) -> 1 | D3: R | E3: RS | F3: PHX | G3: DAL | H3: H | I3: {=IFERROR( Games[[#This Row],[Date]] - LOOKUP( 2, 1/((Games[Team]=Games[[#This Row],[Team]]) * (Games[Date] < Games[[#This Row],[Date]])), Games[Date] ) - 1, Games[[#This Row],[Date]]-$A$2)} -> 0 | J3: {=IFERROR( Games[[#This Row],[Date]] - LOOKUP( 2, 1/((Games[Opponent]=Games[[#This Row],[Opponent]]) * (Games[Date] < Games[[#This Row],[Date]])), Games[Date] ) - 1, Games[[#This Row],[Date]]-$A$2)} -> 0 | K3: =Games[[#This Row],[DaysOff]]-Games[[#This Row],[OppDaysOff]] -> 0 | L3: =Games[[#This Row],[OppDaysOff]]-Games[[#This Row],[DaysOff]] -> 0 | M3: =MAX(-16, MIN(16, Games[[#This Row],[RestDiff]]*8)) -> 0 | N3: =MAX(-16, MIN(16, Games[[#This Row],[OppRestDiff]]*8)) -> 0 | O3: {=IFERROR( LOOKUP( 2, 1/((Games[Team]=Games[[#This Row],[Team]]) * (Games[Season]=Games[[#This Row],[Season]]) * (Games[Date] < Games[[#This Row],[Date]])), Games[PostGmRate] ), IFERROR( alpha * _xlfn.XLOOKUP(Games[[#This Row],[Team]], ConfDiv[TeamID], ConfDiv[PreSeasonElo], base) + (1 - alpha) * base, base ) )} -> 1516.0233 | P3: {=IFERROR( LOOKUP( 2, 1/((Games[Team]=Games[[#This Row],[Opponent]]) * (Games[Season]=Games[[#This Row],[Season]]) * (Games[Date] < Games[[#This Row],[Date]])), Games[PostGmRate] ), IFERROR( alpha * _xlfn.XLOOKUP(Games[[#This Row],[Opponent]], ConfDiv[TeamID], ConfDiv[PreSeasonElo], base) + (1 - alpha) * base, base ) )} -> 1472.3739 | Q3: =1/(1+10^(((Games[[#This Row],[OppPreGmRate]]+IF(Games[[#This Row],[HomeAway]]="A",HCA,0)+Games[[#This Row],[OppRestAdj]])-(Games[[#This Row],[PreGmRate]]+IF(Games[[#This Row],[HomeAway]]="H",HCA,0)+Games[[#This Row],[RestAdj]]))/400)) -> 0.67585972 | R3: 86 | S3: 78 | T3: 0 | U3: =Games[[#This Row],[PointsFor]]-Games[[#This Row],[PointsAgainst]] -> 8 | V3: =IF(Games[[#This Row],[MOV]]>0,1,IF(Games[[#This Row],[MOV]]=0,0.5,0)) -> 1 | W3: =((ABS(Games[[#This Row],[MOV]])+5)^0.6)/(12+0.01*(ABS(Games[[#This Row],[PreGmRate]]-Games[[#This Row],[OppPreGmRate]])))*IF(Games[[#This Row],[OT]]=1,0.9,1) -> 0.37468649 | X3: {=IF(Games[[#This Row],[Type]]="P", _xlfn.IFS( Games[[#This Row],[Round]]=1,1.1, Games[[#This Row],[Round]]=2,1.2, Games[[#This Row],[Round]]=3,1.35, Games[[#This Row],[Round]]=4,1.5,Games[[#This Row],[Round]]=0.5,1.05, TRUE,1 ), 1)} -> 1 | Y3: =MAX(kmin, kmax - 0.15 * MIN(Games[[#This Row],[GamesPlayed]], 82)) -> 75.85 | Z3: =Games[[#This Row],[K]]*Games[[#This Row],[POMult]] -> 75.85 | AA3: =(Games[[#This Row],[Keff]]*Games[[#This Row],[MOVMult]])*(Games[[#This Row],[Result]]-Games[[#This Row],[ExpectedWin%]]) -> 9.2120574 | AB3: =Games[[#This Row],[PreGmRate]]+Games[[#This Row],[RatingChange]] -> 1525.2354 | AC3: =IF(Games[[#This Row],[Type]]="R",IF(Games[[#This Row],[Result]]>0.5,1,0),0) -> 1 | AD3: =IF(Games[[#This Row],[Type]]="R",IF(Games[[#This Row],[Result]]<0.5,1,0),0) -> 0 | AE3: =IF(AND(Games[[#This Row],[Type]]="P",Games[[#This Row],[Round]]=1),IF(Games[[#This Row],[Result]]>0.5,1,0),0) -> 0 | AF3: =IF(AND(Games[[#This Row],[Type]]="P",Games[[#This Row],[Round]]=1),IF(Games[[#This Row],[Result]]<0.5,1,0),0) -> 0 | AG3: =IF(AND(Games[[#This Row],[Type]]="P",Games[[#This Row],[Round]]=2),IF(Games[[#This Row],[Result]]>0.5,1,0),0) -> 0 | AH3: =IF(AND(Games[[#This Row],[Type]]="P",Games[[#This Row],[Round]]=2),IF(Games[[#This Row],[Result]]<0.5,1,0),0) -> 0 | AI3: =IF(AND(Games[[#This Row],[Type]]="P",Games[[#This Row],[Round]]=3),IF(Games[[#This Row],[Result]]>0.5,1,0),0) -> 0 | AJ3: =IF(AND(Games[[#This Row],[Type]]="P",Games[[#This Row],[Round]]=3),IF(Games[[#This Row],[Result]]<0.5,1,0),0) -> 0 | AK3: =IF(AND(Games[[#This Row],[Type]]="P",Games[[#This Row],[Round]]=4),IF(Games[[#This Row],[Result]]>0.5,1,0),0) -> 0 | AL3: =IF(AND(Games[[#This Row],[Type]]="P",Games[[#This Row],[Round]]=4),IF(Games[[#This Row],[Result]]<0.5,1,0),0) -> 0 | AP3: 0.5
A4: 43239 | B4: 2018 | C4: =COUNTIFS(Games[Team],Games[[#This Row],[Team]],Games[Season],Games[[#This Row],[Season]],Games[Date],"<=" & Games[[#This Row],[Date]]) -> 1 | D4: R | E4: RS | F4: CHI | G4: IND | H4: A | I4: {=IFERROR( Games[[#This Row],[Date]] - LOOKUP( 2, 1/((Games[Team]=Games[[#This Row],[Team]]) * (Games[Date] < Games[[#This Row],[Date]])), Games[Date] ) - 1, Games[[#This Row],[Date]]-$A$2)} -> 1 | J4: {=IFERROR( Games[[#This Row],[Date]] - LOOKUP( 2, 1/((Games[Opponent]=Games[[#This Row],[Opponent]]) * (Games[Date] < Games[[#This Row],[Date]])), Games[Date] ) - 1, Games[[#This Row],[Date]]-$A$2)} -> 1 | K4: =Games[[#This Row],[DaysOff]]-Games[[#This Row],[OppDaysOff]] -> 0 | L4: =Games[[#This Row],[OppDaysOff]]-Games[[#This Row],[DaysOff]] -> 0 | M4: =MAX(-16, MIN(16, Games[[#This Row],[RestDiff]]*8)) -> 0 | N4: =MAX(-16, MIN(16, Games[[#This Row],[OppRestDiff]]*8)) -> 0 | O4: {=IFERROR( LOOKUP( 2, 1/((Games[Team]=Games[[#This Row],[Team]]) * (Games[Season]=Games[[#This Row],[Season]]) * (Games[Date] < Games[[#This Row],[Date]])), Games[PostGmRate] ), IFERROR( alpha * _xlfn.XLOOKUP(Games[[#This Row],[Team]], ConfDiv[TeamID], ConfDiv[PreSeasonElo], base) + (1 - alpha) * base, base ) )} -> 1452.8836 | P4: {=IFERROR( LOOKUP( 2, 1/((Games[Team]=Games[[#This Row],[Opponent]]) * (Games[Season]=Games[[#This Row],[Season]]) * (Games[Date] < Games[[#This Row],[Date]])), Games[PostGmRate] ), IFERROR( alpha * _xlfn.XLOOKUP(Games[[#This Row],[Opponent]], ConfDiv[TeamID], ConfDiv[PreSeasonElo], base) + (1 - alpha) * base, base ) )} -> 1410.5264 | Q4: =1/(1+10^(((Games[[#This Row],[OppPreGmRate]]+IF(Games[[#This Row],[HomeAway]]="A",HCA,0)+Games[[#This Row],[OppRestAdj]])-(Games[[#This Row],[PreGmRate]]+IF(Games[[#This Row],[HomeAway]]="H",HCA,0)+Games[[#This Row],[RestAdj]]))/400)) -> 0.4403565 | R4: 82 | S4: 64 | T4: 0 | U4: =Games[[#This Row],[PointsFor]]-Games[[#This Row],[PointsAgainst]] -> 18 | V4: =IF(Games[[#This Row],[MOV]]>0,1,IF(Games[[#This Row],[MOV]]=0,0.5,0)) -> 1 | W4: =((ABS(Games[[#This Row],[MOV]])+5)^0.6)/(12+0.01*(ABS(Games[[#This Row],[PreGmRate]]-Games[[#This Row],[OppPreGmRate]])))*IF(Games[[#This Row],[OT]]=1,0.9,1) -> 0.52819006 | X4: {=IF(Games[[#This Row],[Type]]="P", _xlfn.IFS( Games[[#This Row],[Round]]=1,1.1, Games[[#This Row],[Round]]=2,1.2, Games[[#This Row],[Round]]=3,1.35, Games[[#This Row],[Round]]=4,1.5,Games[[#This Row],[Round]]=0.5,1.05, TRUE,1 ), 1)} -> 1 | Y4: =MAX(kmin, kmax - 0.15 * MIN(Games[[#This Row],[GamesPlayed]], 82)) -> 75.85 | Z4: =Games[[#This Row],[K]]*Games[[#This Row],[POMult]] -> 75.85 | AA4: =(Games[[#This Row],[Keff]]*Games[[#This Row],[MOVMult]])*(Games[[#This Row],[Result]]-Games[[#This Row],[ExpectedWin%]]) -> 22.421118 | AB4: =Games[[#This Row],[PreGmRate]]+Games[[#This Row],[RatingChange]] -> 1475.3047 | AC4: =IF(Games[[#This Row],[Type]]="R",IF(Games[[#This Row],[Result]]>0.5,1,0),0) -> 1 | AD4: =IF(Games[[#This Row],[Type]]="R",IF(Games[[#This Row],[Result]]<0.5,1,0),0) -> 0 | AE4: =IF(AND(Games[[#This Row],[Type]]="P",Games[[#This Row],[Round]]=1),IF(Games[[#This Row],[Result]]>0.5,1,0),0) -> 0 | AF4: =IF(AND(Games[[#This Row],[Type]]="P",Games[[#This Row],[Round]]=1),IF(Games[[#This Row],[Result]]<0.5,1,0),0) -> 0 | AG4: =IF(AND(Games[[#This Row],[Type]]="P",Games[[#This Row],[Round]]=2),IF(Games[[#This Row],[Result]]>0.5,1,0),0) -> 0 | AH4: =IF(AND(Games[[#This Row],[Type]]="P",Games[[#This Row],[Round]]=2),IF(Games[[#This Row],[Result]]<0.5,1,0),0) -> 0 | AI4: =IF(AND(Games[[#This Row],[Type]]="P",Games[[#This Row],[Round]]=3),IF(Games[[#This Row],[Result]]>0.5,1,0),0) -> 0 | AJ4: =IF(AND(Games[[#This Row],[Type]]="P",Games[[#This Row],[Round]]=3),IF(Games[[#This Row],[Result]]<0.5,1,0),0) -> 0 | AK4: =IF(AND(Games[[#This Row],[Type]]="P",Games[[#This Row],[Round]]=4),IF(Games[[#This Row],[Result]]>0.5,1,0),0) -> 0 | AL4: =IF(AND(Games[[#This Row],[Type]]="P",Games[[#This Row],[Round]]=4),IF(Games[[#This Row],[Result]]<0.5,1,0),0) -> 0 | AP4: 1500
A5: 43239 | B5: 2018 | C5: =COUNTIFS(Games[Team],Games[[#This Row],[Team]],Games[Season],Games[[#This Row],[Season]],Games[Date],"<=" & Games[[#This Row],[Date]]) -> 1 | D5: R | E5: RS | F5: IND | G5: CHI | H5: H | I5: {=IFERROR( Games[[#This Row],[Date]] - LOOKUP( 2, 1/((Games[Team]=Games[[#This Row],[Team]]) * (Games[Date] < Games[[#This Row],[Date]])), Games[Date] ) - 1, Games[[#This Row],[Date]]-$A$2)} -> 1 | J5: {=IFERROR( Games[[#This Row],[Date]] - LOOKUP( 2, 1/((Games[Opponent]=Games[[#This Row],[Opponent]]) * (Games[Date] < Games[[#This Row],[Date]])), Games[Date] ) - 1, Games[[#This Row],[Date]]-$A$2)} -> 1 | K5: =Games[[#This Row],[DaysOff]]-Games[[#This Row],[OppDaysOff]] -> 0 | L5: =Games[[#This Row],[OppDaysOff]]-Games[[#This Row],[DaysOff]] -> 0 | M5: =MAX(-16, MIN(16, Games[[#This Row],[RestDiff]]*8)) -> 0 | N5: =MAX(-16, MIN(16, Games[[#This Row],[OppRestDiff]]*8)) -> 0 | O5: {=IFERROR( LOOKUP( 2, 1/((Games[Team]=Games[[#This Row],[Team]]) * (Games[Season]=Games[[#This Row],[Season]]) * (Games[Date] < Games[[#This Row],[Date]])), Games[PostGmRate] ), IFERROR( alpha * _xlfn.XLOOKUP(Games[[#This Row],[Team]], ConfDiv[TeamID], ConfDiv[PreSeasonElo], base) + (1 - alpha) * base, base ) )} -> 1410.5264 | P5: {=IFERROR( LOOKUP( 2, 1/((Games[Team]=Games[[#This Row],[Opponent]]) * (Games[Season]=Games[[#This Row],[Season]]) * (Games[Date] < Games[[#This Row],[Date]])), Games[PostGmRate] ), IFERROR( alpha * _xlfn.XLOOKUP(Games[[#This Row],[Opponent]], ConfDiv[TeamID], ConfDiv[PreSeasonElo], base) + (1 - alpha) * base, base ) )} -> 1452.8836 | Q5: =1/(1+10^(((Games[[#This Row],[OppPreGmRate]]+IF(Games[[#This Row],[HomeAway]]="A",HCA,0)+Games[[#This Row],[OppRestAdj]])-(Games[[#This Row],[PreGmRate]]+IF(Games[[#This Row],[HomeAway]]="H",HCA,0)+Games[[#This Row],[RestAdj]]))/400)) -> 0.5596435 | R5: 64 | S5: 82 | T5: 0 | U5: =Games[[#This Row],[PointsFor]]-Games[[#This Row],[PointsAgainst]] -> -18 | V5: =IF(Games[[#This Row],[MOV]]>0,1,IF(Games[[#This Row],[MOV]]=0,0.5,0)) -> 0 | W5: =((ABS(Games[[#This Row],[MOV]])+5)^0.6)/(12+0.01*(ABS(Games[[#This Row],[PreGmRate]]-Games[[#This Row],[OppPreGmRate]])))*IF(Games[[#This Row],[OT]]=1,0.9,1) -> 0.52819006 | X5: {=IF(Games[[#This Row],[Type]]="P", _xlfn.IFS( Games[[#This Row],[Round]]=1,1.1, Games[[#This Row],[Round]]=2,1.2, Games[[#This Row],[Round]]=3,1.35, Games[[#This Row],[Round]]=4,1.5,Games[[#This Row],[Round]]=0.5,1.05, TRUE,1 ), 1)} -> 1 | Y5: =MAX(kmin, kmax - 0.15 * MIN(Games[[#This Row],[GamesPlayed]], 82)) -> 75.85 | Z5: =Games[[#This Row],[K]]*Games[[#This Row],[POMult]] -> 75.85 | AA5: =(Games[[#This Row],[Keff]]*Games[[#This Row],[MOVMult]])*(Games[[#This Row],[Result]]-Games[[#This Row],[ExpectedWin%]]) -> -22.421118 | AB5: =Games[[#This Row],[PreGmRate]]+Games[[#This Row],[RatingChange]] -> 1388.1053 | AC5: =IF(Games[[#This Row],[Type]]="R",IF(Games[[#This Row],[Result]]>0.5,1,0),0) -> 0 | AD5: =IF(Games[[#This Row],[Type]]="R",IF(Games[[#This Row],[Result]]<0.5,1,0),0) -> 1 | AE5: =IF(AND(Games[[#This Row],[Type]]="P",Games[[#This Row],[Round]]=1),IF(Games[[#This Row],[Result]]>0.5,1,0),0) -> 0 | AF5: =IF(AND(Games[[#This Row],[Type]]="P",Games[[#This Row],[Round]]=1),IF(Games[[#This Row],[Result]]<0.5,1,0),0) -> 0 | AG5: =IF(AND(Games[[#This Row],[Type]]="P",Games[[#This Row],[Round]]=2),IF(Games[[#This Row],[Result]]>0.5,1,0),0) -> 0 | AH5: =IF(AND(Games[[#This Row],[Type]]="P",Games[[#This Row],[Round]]=2),IF(Games[[#This Row],[Result]]<0.5,1,0),0) -> 0 | AI5: =IF(AND(Games[[#This Row],[Type]]="P",Games[[#This Row],[Round]]=3),IF(Games[[#This Row],[Result]]>0.5,1,0),0) -> 0 | AJ5: =IF(AND(Games[[#This Row],[Type]]="P",Games[[#This Row],[Round]]=3),IF(Games[[#This Row],[Result]]<0.5,1,0),0) -> 0 | AK5: =IF(AND(Games[[#This Row],[Type]]="P",Games[[#This Row],[Round]]=4),IF(Games[[#This Row],[Result]]>0.5,1,0),0) -> 0 | AL5: =IF(AND(Games[[#This Row],[Type]]="P",Games[[#This Row],[Round]]=4),IF(Games[[#This Row],[Result]]<0.5,1,0),0) -> 0
A6: 43240 | B6: 2018 | C6: =COUNTIFS(Games[Team],Games[[#This Row],[Team]],Games[Season],Games[[#This Row],[Season]],Games[Date],"<=" & Games[[#This Row],[Date]]) -> 1 | D6: R | E6: RS | F6: NYL | G6: CHI | H6: A | I6: {=IFERROR( Games[[#This Row],[Date]] - LOOKUP( 2, 1/((Games[Team]=Games[[#This Row],[Team]]) * (Games[Date] < Games[[#This Row],[Date]])), Games[Date] ) - 1, Games[[#This Row],[Date]]-$A$2)} -> 2 | J6: {=IFERROR( Games[[#This Row],[Date]] - LOOKUP( 2, 1/((Games[Opponent]=Games[[#This Row],[Opponent]]) * (Games[Date] < Games[[#This Row],[Date]])), Games[Date] ) - 1, Games[[#This Row],[Date]]-$A$2)} -> 0 | K6: =Games[[#This Row],[DaysOff]]-Games[[#This Row],[OppDaysOff]] -> 2 | L6: =Games[[#This Row],[OppDaysOff]]-Games[[#This Row],[DaysOff]] -> -2 | M6: =MAX(-16, MIN(16, Games[[#This Row],[RestDiff]]*8)) -> 16 | N6: =MAX(-16, MIN(16, Games[[#This Row],[OppRestDiff]]*8)) -> -16 | O6: {=IFERROR( LOOKUP( 2, 1/((Games[Team]=Games[[#This Row],[Team]]) * (Games[Season]=Games[[#This Row],[Season]]) * (Games[Date] < Games[[#This Row],[Date]])), Games[PostGmRate] ), IFERROR( alpha * _xlfn.XLOOKUP(Games[[#This Row],[Team]], ConfDiv[TeamID], ConfDiv[PreSeasonElo], base) + (1 - alpha) * base, base ) )} -> 1542.1445 | P6: {=IFERROR( LOOKUP( 2, 1/((Games[Team]=Games[[#This Row],[Opponent]]) * (Games[Season]=Games[[#This Row],[Season]]) * (Games[Date] < Games[[#This Row],[Date]])), Games[PostGmRate] ), IFERROR( alpha * _xlfn.XLOOKUP(Games[[#This Row],[Opponent]], ConfDiv[TeamID], ConfDiv[PreSeasonElo], base) + (1 - alpha) * base, base ) )} -> 1475.3047 | Q6: =1/(1+10^(((Games[[#This Row],[OppPreGmRate]]+IF(Games[[#This Row],[HomeAway]]="A",HCA,0)+Games[[#This Row],[OppRestAdj]])-(Games[[#This Row],[PreGmRate]]+IF(Games[[#This Row],[HomeAway]]="H",HCA,0)+Games[[#This Row],[RestAdj]]))/400)) -> 0.52134318 | R6: 76 | S6: 80 | T6: 0 | U6: =Games[[#This Row],[PointsFor]]-Games[[#This Row],[PointsAgainst]] -> -4 | V6: =IF(Games[[#This Row],[MOV]]>0,1,IF(Games[[#This Row],[MOV]]=0,0.5,0)) -> 0 | W6: =((ABS(Games[[#This Row],[MOV]])+5)^0.6)/(12+0.01*(ABS(Games[[#This Row],[PreGmRate]]-Games[[#This Row],[OppPreGmRate]])))*IF(Games[[#This Row],[OT]]=1,0.9,1) -> 0.29500122 | X6: {=IF(Games[[#This Row],[Type]]="P", _xlfn.IFS( Games[[#This Row],[Round]]=1,1.1, Games[[#This Row],[Round]]=2,1.2, Games[[#This Row],[Round]]=3,1.35, Games[[#This Row],[Round]]=4,1.5,Games[[#This Row],[Round]]=0.5,1.05, TRUE,1 ), 1)} -> 1 | Y6: =MAX(kmin, kmax - 0.15 * MIN(Games[[#This Row],[GamesPlayed]], 82)) -> 75.85 | Z6: =Games[[#This Row],[K]]*Games[[#This Row],[POMult]] -> 75.85 | AA6: =(Games[[#This Row],[Keff]]*Games[[#This Row],[MOVMult]])*(Games[[#This Row],[Result]]-Games[[#This Row],[ExpectedWin%]]) -> -11.665493 | AB6: =Games[[#This Row],[PreGmRate]]+Games[[#This Row],[RatingChange]] -> 1530.479 | AC6: =IF(Games[[#This Row],[Type]]="R",IF(Games[[#This Row],[Result]]>0.5,1,0),0) -> 0 | AD6: =IF(Games[[#This Row],[Type]]="R",IF(Games[[#This Row],[Result]]<0.5,1,0),0) -> 1 | AE6: =IF(AND(Games[[#This Row],[Type]]="P",Games[[#This Row],[Round]]=1),IF(Games[[#This Row],[Result]]>0.5,1,0),0) -> 0 | AF6: =IF(AND(Games[[#This Row],[Type]]="P",Games[[#This Row],[Round]]=1),IF(Games[[#This Row],[Result]]<0.5,1,0),0) -> 0 | AG6: =IF(AND(Games[[#This Row],[Type]]="P",Games[[#This Row],[Round]]=2),IF(Games[[#This Row],[Result]]>0.5,1,0),0) -> 0 | AH6: =IF(AND(Games[[#This Row],[Type]]="P",Games[[#This Row],[Round]]=2),IF(Games[[#This Row],[Result]]<0.5,1,0),0) -> 0 | AI6: =IF(AND(Games[[#This Row],[Type]]="P",Games[[#This Row],[Round]]=3),IF(Games[[#This Row],[Result]]>0.5,1,0),0) -> 0 | AJ6: =IF(AND(Games[[#This Row],[Type]]="P",Games[[#This Row],[Round]]=3),IF(Games[[#This Row],[Result]]<0.5,1,0),0) -> 0 | AK6: =IF(AND(Games[[#This Row],[Type]]="P",Games[[#This Row],[Round]]=4),IF(Games[[#This Row],[Result]]>0.5,1,0),0) -> 0 | AL6: =IF(AND(Games[[#This Row],[Type]]="P",Games[[#This Row],[Round]]=4),IF(Games[[#This Row],[Result]]<0.5,1,0),0) -> 0
A7: 43240 | B7: 2018 | C7: =COUNTIFS(Games[Team],Games[[#This Row],[Team]],Games[Season],Games[[#This Row],[Season]],Games[Date],"<=" & Games[[#This Row],[Date]]) -> 2 | D7: R | E7: RS | F7: CHI | G7: NYL | H7: H | I7: {=IFERROR( Games[[#This Row],[Date]] - LOOKUP( 2, 1/((Games[Team]=Games[[#This Row],[Team]]) * (Games[Date] < Games[[#This Row],[Date]])), Games[Date] ) - 1, Games[[#This Row],[Date]]-$A$2)} -> 0 | J7: {=IFERROR( Games[[#This Row],[Date]] - LOOKUP( 2, 1/((Games[Opponent]=Games[[#This Row],[Opponent]]) * (Games[Date] < Games[[#This Row],[Date]])), Games[Date] ) - 1, Games[[#This Row],[Date]]-$A$2)} -> 2 | K7: =Games[[#This Row],[DaysOff]]-Games[[#This Row],[OppDaysOff]] -> -2 | L7: =Games[[#This Row],[OppDaysOff]]-Games[[#This Row],[DaysOff]] -> 2 | M7: =MAX(-16, MIN(16, Games[[#This Row],[RestDiff]]*8)) -> -16 | N7: =MAX(-16, MIN(16, Games[[#This Row],[OppRestDiff]]*8)) -> 16 | O7: {=IFERROR( LOOKUP( 2, 1/((Games[Team]=Games[[#This Row],[Team]]) * (Games[Season]=Games[[#This Row],[Season]]) * (Games[Date] < Games[[#This Row],[Date]])), Games[PostGmRate] ), IFERROR( alpha * _xlfn.XLOOKUP(Games[[#This Row],[Team]], ConfDiv[TeamID], ConfDiv[PreSeasonElo], base) + (1 - alpha) * base, base ) )} -> 1475.3047 | P7: {=IFERROR( LOOKUP( 2, 1/((Games[Team]=Games[[#This Row],[Opponent]]) * (Games[Season]=Games[[#This Row],[Season]]) * (Games[Date] < Games[[#This Row],[Date]])), Games[PostGmRate] ), IFERROR( alpha * _xlfn.XLOOKUP(Games[[#This Row],[Opponent]], ConfDiv[TeamID], ConfDiv[PreSeasonElo], base) + (1 - alpha) * base, base ) )} -> 1542.1445 | Q7: =1/(1+10^(((Games[[#This Row],[OppPreGmRate]]+IF(Games[[#This Row],[HomeAway]]="A",HCA,0)+Games[[#This Row],[OppRestAdj]])-(Games[[#This Row],[PreGmRate]]+IF(Games[[#This Row],[HomeAway]]="H",HCA,0)+Games[[#This Row],[RestAdj]]))/400)) -> 0.47865682 | R7: 80 | S7: 76 | T7: 0 | U7: =Games[[#This Row],[PointsFor]]-Games[[#This Row],[PointsAgainst]] -> 4 | V7: =IF(Games[[#This Row],[MOV]]>0,1,IF(Games[[#This Row],[MOV]]=0,0.5,0)) -> 1 | W7: =((ABS(Games[[#This Row],[MOV]])+5)^0.6)/(12+0.01*(ABS(Games[[#This Row],[PreGmRate]]-Games[[#This Row],[OppPreGmRate]])))*IF(Games[[#This Row],[OT]]=1,0.9,1) -> 0.29500122 | X7: {=IF(Games[[#This Row],[Type]]="P", _xlfn.IFS( Games[[#This Row],[Round]]=1,1.1, Games[[#This Row],[Round]]=2,1.2, Games[[#This Row],[Round]]=3,1.35, Games[[#This Row],[Round]]=4,1.5,Games[[#This Row],[Round]]=0.5,1.05, TRUE,1 ), 1)} -> 1 | Y7: =MAX(kmin, kmax - 0.15 * MIN(Games[[#This Row],[GamesPlayed]], 82)) -> 75.7 | Z7: =Games[[#This Row],[K]]*Games[[#This Row],[POMult]] -> 75.7 | AA7: =(Games[[#This Row],[Keff]]*Games[[#This Row],[MOVMult]])*(Games[[#This Row],[Result]]-Games[[#This Row],[ExpectedWin%]]) -> 11.642423 | AB7: =Games[[#This Row],[PreGmRate]]+Games[[#This Row],[RatingChange]] -> 1486.9471 | AC7: =IF(Games[[#This Row],[Type]]="R",IF(Games[[#This Row],[Result]]>0.5,1,0),0) -> 1 | AD7: =IF(Games[[#This Row],[Type]]="R",IF(Games[[#This Row],[Result]]<0.5,1,0),0) -> 0 | AE7: =IF(AND(Games[[#This Row],[Type]]="P",Games[[#This Row],[Round]]=1),IF(Games[[#This Row],[Result]]>0.5,1,0),0) -> 0 | AF7: =IF(AND(Games[[#This Row],[Type]]="P",Games[[#This Row],[Round]]=1),IF(Games[[#This Row],[Result]]<0.5,1,0),0) -> 0 | AG7: =IF(AND(Games[[#This Row],[Type]]="P",Games[[#This Row],[Round]]=2),IF(Games[[#This Row],[Result]]>0.5,1,0),0) -> 0 | AH7: =IF(AND(Games[[#This Row],[Type]]="P",Games[[#This Row],[Round]]=2),IF(Games[[#This Row],[Result]]<0.5,1,0),0) -> 0 | AI7: =IF(AND(Games[[#This Row],[Type]]="P",Games[[#This Row],[Round]]=3),IF(Games[[#This Row],[Result]]>0.5,1,0),0) -> 0 | AJ7: =IF(AND(Games[[#This Row],[Type]]="P",Games[[#This Row],[Round]]=3),IF(Games[[#This Row],[Result]]<0.5,1,0),0) -> 0 | AK7: =IF(AND(Games[[#This Row],[Type]]="P",Games[[#This Row],[Round]]=4),IF(Games[[#This Row],[Result]]>0.5,1,0),0) -> 0 | AL7: =IF(AND(Games[[#This Row],[Type]]="P",Games[[#This Row],[Round]]=4),IF(Games[[#This Row],[Result]]<0.5,1,0),0) -> 0
A8: 43240 | B8: 2018 | C8: =COUNTIFS(Games[Team],Games[[#This Row],[Team]],Games[Season],Games[[#This Row],[Season]],Games[Date],"<=" & Games[[#This Row],[Date]]) -> 1 | D8: R | E8: RS | F8: LVA | G8: CON | H8: A | I8: {=IFERROR( Games[[#This Row],[Date]] - LOOKUP( 2, 1/((Games[Team]=Games[[#This Row],[Team]]) * (Games[Date] < Games[[#This Row],[Date]])), Games[Date] ) - 1, Games[[#This Row],[Date]]-$A$2)} -> 2 | J8: {=IFERROR( Games[[#This Row],[Date]] - LOOKUP( 2, 1/((Games[Opponent]=Games[[#This Row],[Opponent]]) * (Games[Date] < Games[[#This Row],[Date]])), Games[Date] ) - 1, Games[[#This Row],[Date]]-$A$2)} -> 2 | K8: =Games[[#This Row],[DaysOff]]-Games[[#This Row],[OppDaysOff]] -> 0 | L8: =Games[[#This Row],[OppDaysOff]]-Games[[#This Row],[DaysOff]] -> 0 | M8: =MAX(-16, MIN(16, Games[[#This Row],[RestDiff]]*8)) -> 0 | N8: =MAX(-16, MIN(16, Games[[#This Row],[OppRestDiff]]*8)) -> 0 | O8: {=IFERROR( LOOKUP( 2, 1/((Games[Team]=Games[[#This Row],[Team]]) * (Games[Season]=Games[[#This Row],[Season]]) * (Games[Date] < Games[[#This Row],[Date]])), Games[PostGmRate] ), IFERROR( alpha * _xlfn.XLOOKUP(Games[[#This Row],[Team]], ConfDiv[TeamID], ConfDiv[PreSeasonElo], base) + (1 - alpha) * base, base ) )} -> 1422.4123 | P8: {=IFERROR( LOOKUP( 2, 1/((Games[Team]=Games[[#This Row],[Opponent]]) * (Games[Season]=Games[[#This Row],[Season]]) * (Games[Date] < Games[[#This Row],[Date]])), Games[PostGmRate] ), IFERROR( alpha * _xlfn.XLOOKUP(Games[[#This Row],[Opponent]], ConfDiv[TeamID], ConfDiv[PreSeasonElo], base) + (1 - alpha) * base, base ) )} -> 1523.7613 | Q8: =1/(1+10^(((Games[[#This Row],[OppPreGmRate]]+IF(Games[[#This Row],[HomeAway]]="A",HCA,0)+Games[[#This Row],[OppRestAdj]])-(Games[[#This Row],[PreGmRate]]+IF(Games[[#This Row],[HomeAway]]="H",HCA,0)+Games[[#This Row],[RestAdj]]))/400)) -> 0.25598268 | R8: 65 | S8: 101 | T8: 0 | U8: =Games[[#This Row],[PointsFor]]-Games[[#This Row],[PointsAgainst]] -> -36 | V8: =IF(Games[[#This Row],[MOV]]>0,1,IF(Games[[#This Row],[MOV]]=0,0.5,0)) -> 0 | W8: =((ABS(Games[[#This Row],[MOV]])+5)^0.6)/(12+0.01*(ABS(Games[[#This Row],[PreGmRate]]-Games[[#This Row],[OppPreGmRate]])))*IF(Games[[#This Row],[OT]]=1,0.9,1) -> 0.71330708 | X8: {=IF(Games[[#This Row],[Type]]="P", _xlfn.IFS( Games[[#This Row],[Round]]=1,1.1, Games[[#This Row],[Round]]=2,1.2, Games[[#This Row],[Round]]=3,1.35, Games[[#This Row],[Round]]=4,1.5,Games[[#This Row],[Round]]=0.5,1.05, TRUE,1 ), 1)} -> 1 | Y8: =MAX(kmin, kmax - 0.15 * MIN(Games[[#This Row],[GamesPlayed]], 82)) -> 75.85 | Z8: =Games[[#This Row],[K]]*Games[[#This Row],[POMult]] -> 75.85 | AA8: =(Games[[#This Row],[Keff]]*Games[[#This Row],[MOVMult]])*(Games[[#This Row],[Result]]-Games[[#This Row],[ExpectedWin%]]) -> -13.849775 | AB8: =Games[[#This Row],[PreGmRate]]+Games[[#This Row],[RatingChange]] -> 1408.5626 | AC8: =IF(Games[[#This Row],[Type]]="R",IF(Games[[#This Row],[Result]]>0.5,1,0),0) -> 0 | AD8: =IF(Games[[#This Row],[Type]]="R",IF(Games[[#This Row],[Result]]<0.5,1,0),0) -> 1 | AE8: =IF(AND(Games[[#This Row],[Type]]="P",Games[[#This Row],[Round]]=1),IF(Games[[#This Row],[Result]]>0.5,1,0),0) -> 0 | AF8: =IF(AND(Games[[#This Row],[Type]]="P",Games[[#This Row],[Round]]=1),IF(Games[[#This Row],[Result]]<0.5,1,0),0) -> 0 | AG8: =IF(AND(Games[[#This Row],[Type]]="P",Games[[#This Row],[Round]]=2),IF(Games[[#This Row],[Result]]>0.5,1,0),0) -> 0 | AH8: =IF(AND(Games[[#This Row],[Type]]="P",Games[[#This Row],[Round]]=2),IF(Games[[#This Row],[Result]]<0.5,1,0),0) -> 0 | AI8: =IF(AND(Games[[#This Row],[Type]]="P",Games[[#This Row],[Round]]=3),IF(Games[[#This Row],[Result]]>0.5,1,0),0) -> 0 | AJ8: =IF(AND(Games[[#This Row],[Type]]="P",Games[[#This Row],[Round]]=3),IF(Games[[#This Row],[Result]]<0.5,1,0),0) -> 0 | AK8: =IF(AND(Games[[#This Row],[Type]]="P",Games[[#This Row],[Round]]=4),IF(Games[[#This Row],[Result]]>0.5,1,0),0) -> 0 | AL8: =IF(AND(Games[[#This Row],[Type]]="P",Games[[#This Row],[Round]]=4),IF(Games[[#This Row],[Result]]<0.5,1,0),0) -> 0
A9: 43240 | B9: 2018 | C9: =COUNTIFS(Games[Team],Games[[#This Row],[Team]],Games[Season],Games[[#This Row],[Season]],Games[Date],"<=" & Games[[#This Row],[Date]]) -> 1 | D9: R | E9: RS | F9: CON | G9: LVA | H9: H | I9: {=IFERROR( Games[[#This Row],[Date]] - LOOKUP( 2, 1/((Games[Team]=Games[[#This Row],[Team]]) * (Games[Date] < Games[[#This Row],[Date]])), Games[Date] ) - 1, Games[[#This Row],[Date]]-$A$2)} -> 2 | J9: {=IFERROR( Games[[#This Row],[Date]] - LOOKUP( 2, 1/((Games[Opponent]=Games[[#This Row],[Opponent]]) * (Games[Date] < Games[[#This Row],[Date]])), Games[Date] ) - 1, Games[[#This Row],[Date]]-$A$2)} -> 2 | K9: =Games[[#This Row],[DaysOff]]-Games[[#This Row],[OppDaysOff]] -> 0 | L9: =Games[[#This Row],[OppDaysOff]]-Games[[#This Row],[DaysOff]] -> 0 | M9: =MAX(-16, MIN(16, Games[[#This Row],[RestDiff]]*8)) -> 0 | N9: =MAX(-16, MIN(16, Games[[#This Row],[OppRestDiff]]*8)) -> 0 | O9: {=IFERROR( LOOKUP( 2, 1/((Games[Team]=Games[[#This Row],[Team]]) * (Games[Season]=Games[[#This Row],[Season]]) * (Games[Date] < Games[[#This Row],[Date]])), Games[PostGmRate] ), IFERROR( alpha * _xlfn.XLOOKUP(Games[[#This Row],[Team]], ConfDiv[TeamID], ConfDiv[PreSeasonElo], base) + (1 - alpha) * base, base ) )} -> 1523.7613 | P9: {=IFERROR( LOOKUP( 2, 1/((Games[Team]=Games[[#This Row],[Opponent]]) * (Games[Season]=Games[[#This Row],[Season]]) * (Games[Date] < Games[[#This Row],[Date]])), Games[PostGmRate] ), IFERROR( alpha * _xlfn.XLOOKUP(Games[[#This Row],[Opponent]], ConfDiv[TeamID], ConfDiv[PreSeasonElo], base) + (1 - alpha) * base, base ) )} -> 1422.4123 | Q9: =1/(1+10^(((Games[[#This Row],[OppPreGmRate]]+IF(Games[[#This Row],[HomeAway]]="A",HCA,0)+Games[[#This Row],[OppRestAdj]])-(Games[[#This Row],[PreGmRate]]+IF(Games[[#This Row],[HomeAway]]="H",HCA,0)+Games[[#This Row],[RestAdj]]))/400)) -> 0.74401732 | R9: 101 | S9: 65 | T9: 0 | U9: =Games[[#This Row],[PointsFor]]-Games[[#This Row],[PointsAgainst]] -> 36 | V9: =IF(Games[[#This Row],[MOV]]>0,1,IF(Games[[#This Row],[MOV]]=0,0.5,0)) -> 1 | W9: =((ABS(Games[[#This Row],[MOV]])+5)^0.6)/(12+0.01*(ABS(Games[[#This Row],[PreGmRate]]-Games[[#This Row],[OppPreGmRate]])))*IF(Games[[#This Row],[OT]]=1,0.9,1) -> 0.71330708 | X9: {=IF(Games[[#This Row],[Type]]="P", _xlfn.IFS( Games[[#This Row],[Round]]=1,1.1, Games[[#This Row],[Round]]=2,1.2, Games[[#This Row],[Round]]=3,1.35, Games[[#This Row],[Round]]=4,1.5,Games[[#This Row],[Round]]=0.5,1.05, TRUE,1 ), 1)} -> 1 | Y9: =MAX(kmin, kmax - 0.15 * MIN(Games[[#This Row],[GamesPlayed]], 82)) -> 75.85 | Z9: =Games[[#This Row],[K]]*Games[[#This Row],[POMult]] -> 75.85 | AA9: =(Games[[#This Row],[Keff]]*Games[[#This Row],[MOVMult]])*(Games[[#This Row],[Result]]-Games[[#This Row],[ExpectedWin%]]) -> 13.849775 | AB9: =Games[[#This Row],[PreGmRate]]+Games[[#This Row],[RatingChange]] -> 1537.6111 | AC9: =IF(Games[[#This Row],[Type]]="R",IF(Games[[#This Row],[Result]]>0.5,1,0),0) -> 1 | AD9: =IF(Games[[#This Row],[Type]]="R",IF(Games[[#This Row],[Result]]<0.5,1,0),0) -> 0 | AE9: =IF(AND(Games[[#This Row],[Type]]="P",Games[[#This Row],[Round]]=1),IF(Games[[#This Row],[Result]]>0.5,1,0),0) -> 0 | AF9: =IF(AND(Games[[#This Row],[Type]]="P",Games[[#This Row],[Round]]=1),IF(Games[[#This Row],[Result]]<0.5,1,0),0) -> 0 | AG9: =IF(AND(Games[[#This Row],[Type]]="P",Games[[#This Row],[Round]]=2),IF(Games[[#This Row],[Result]]>0.5,1,0),0) -> 0 | AH9: =IF(AND(Games[[#This Row],[Type]]="P",Games[[#This Row],[Round]]=2),IF(Games[[#This Row],[Result]]<0.5,1,0),0) -> 0 | AI9: =IF(AND(Games[[#This Row],[Type]]="P",Games[[#This Row],[Round]]=3),IF(Games[[#This Row],[Result]]>0.5,1,0),0) -> 0 | AJ9: =IF(AND(Games[[#This Row],[Type]]="P",Games[[#This Row],[Round]]=3),IF(Games[[#This Row],[Result]]<0.5,1,0),0) -> 0 | AK9: =IF(AND(Games[[#This Row],[Type]]="P",Games[[#This Row],[Round]]=4),IF(Games[[#This Row],[Result]]>0.5,1,0),0) -> 0 | AL9: =IF(AND(Games[[#This Row],[Type]]="P",Games[[#This Row],[Round]]=4),IF(Games[[#This Row],[Result]]<0.5,1,0),0) -> 0
A10: 43240 | B10: 2018 | C10: =COUNTIFS(Games[Team],Games[[#This Row],[Team]],Games[Season],Games[[#This Row],[Season]],Games[Date],"<=" & Games[[#This Row],[Date]]) -> 1 | D10: R | E10: RS | F10: ATL | G10: DAL | H10: A | I10: {=IFERROR( Games[[#This Row],[Date]] - LOOKUP( 2, 1/((Games[Team]=Games[[#This Row],[Team]]) * (Games[Date] < Games[[#This Row],[Date]])), Games[Date] ) - 1, Games[[#This Row],[Date]]-$A$2)} -> 2 | J10: {=IFERROR( Games[[#This Row],[Date]] - LOOKUP( 2, 1/((Games[Opponent]=Games[[#This Row],[Opponent]]) * (Games[Date] < Games[[#This Row],[Date]])), Games[Date] ) - 1, Games[[#This Row],[Date]]-$A$2)} -> 1 | K10: =Games[[#This Row],[DaysOff]]-Games[[#This Row],[OppDaysOff]] -> 1 | L10: =Games[[#This Row],[OppDaysOff]]-Games[[#This Row],[DaysOff]] -> -1 | M10: =MAX(-16, MIN(16, Games[[#This Row],[RestDiff]]*8)) -> 8 | N10: =MAX(-16, MIN(16, Games[[#This Row],[OppRestDiff]]*8)) -> -8 | O10: {=IFERROR( LOOKUP( 2, 1/((Games[Team]=Games[[#This Row],[Team]]) * (Games[Season]=Games[[#This Row],[Season]]) * (Games[Date] < Games[[#This Row],[Date]])), Games[PostGmRate] ), IFERROR( alpha * _xlfn.XLOOKUP(Games[[#This Row],[Team]], ConfDiv[TeamID], ConfDiv[PreSeasonElo], base) + (1 - alpha) * base, base ) )} -> 1448.8555 | P10: {=IFERROR( LOOKUP( 2, 1/((Games[Team]=Games[[#This Row],[Opponent]]) * (Games[Season]=Games[[#This Row],[Season]]) * (Games[Date] < Games[[#This Row],[Date]])), Games[PostGmRate] ), IFERROR( alpha * _xlfn.XLOOKUP(Games[[#This Row],[Opponent]], ConfDiv[TeamID], ConfDiv[PreSeasonElo], base) + (1 - alpha) * base, base ) )} -> 1463.1619 | Q10: =1/(1+10^(((Games[[#This Row],[OppPreGmRate]]+IF(Games[[#This Row],[HomeAway]]="A",HCA,0)+Games[[#This Row],[OppRestAdj]])-(Games[[#This Row],[PreGmRate]]+IF(Games[[#This Row],[HomeAway]]="H",HCA,0)+Games[[#This Row],[RestAdj]]))/400)) -> 0.38371882 | R10: 78 | S10: 101 | T10: 0 | U10: =Games[[#This Row],[PointsFor]]-Games[[#This Row],[PointsAgainst]] -> -23 | V10: =IF(Games[[#This Row],[MOV]]>0,1,IF(Games[[#This Row],[MOV]]=0,0.5,0)) -> 0 | W10: =((ABS(Games[[#This Row],[MOV]])+5)^0.6)/(12+0.01*(ABS(Games[[#This Row],[PreGmRate]]-Games[[#This Row],[OppPreGmRate]])))*IF(Games[[#This Row],[OT]]=1,0.9,1) -> 0.60808818 | X10: {=IF(Games[[#This Row],[Type]]="P", _xlfn.IFS( Games[[#This Row],[Round]]=1,1.1, Games[[#This Row],[Round]]=2,1.2, Games[[#This Row],[Round]]=3,1.35, Games[[#This Row],[Round]]=4,1.5,Games[[#This Row],[Round]]=0.5,1.05, TRUE,1 ), 1)} -> 1 | Y10: =MAX(kmin, kmax - 0.15 * MIN(Games[[#This Row],[GamesPlayed]], 82)) -> 75.85 | Z10: =Games[[#This Row],[K]]*Games[[#This Row],[POMult]] -> 75.85 | AA10: =(Games[[#This Row],[Keff]]*Games[[#This Row],[MOVMult]])*(Games[[#This Row],[Result]]-Games[[#This Row],[ExpectedWin%]]) -> -17.698451 | AB10: =Games[[#This Row],[PreGmRate]]+Games[[#This Row],[RatingChange]] -> 1431.1571 | AC10: =IF(Games[[#This Row],[Type]]="R",IF(Games[[#This Row],[Result]]>0.5,1,0),0) -> 0 | AD10: =IF(Games[[#This Row],[Type]]="R",IF(Games[[#This Row],[Result]]<0.5,1,0),0) -> 1 | AE10: =IF(AND(Games[[#This Row],[Type]]="P",Games[[#This Row],[Round]]=1),IF(Games[[#This Row],[Result]]>0.5,1,0),0) -> 0 | AF10: =IF(AND(Games[[#This Row],[Type]]="P",Games[[#This Row],[Round]]=1),IF(Games[[#This Row],[Result]]<0.5,1,0),0) -> 0 | AG10: =IF(AND(Games[[#This Row],[Type]]="P",Games[[#This Row],[Round]]=2),IF(Games[[#This Row],[Result]]>0.5,1,0),0) -> 0 | AH10: =IF(AND(Games[[#This Row],[Type]]="P",Games[[#This Row],[Round]]=2),IF(Games[[#This Row],[Result]]<0.5,1,0),0) -> 0 | AI10: =IF(AND(Games[[#This Row],[Type]]="P",Games[[#This Row],[Round]]=3),IF(Games[[#This Row],[Result]]>0.5,1,0),0) -> 0 | AJ10: =IF(AND(Games[[#This Row],[Type]]="P",Games[[#This Row],[Round]]=3),IF(Games[[#This Row],[Result]]<0.5,1,0),0) -> 0 | AK10: =IF(AND(Games[[#This Row],[Type]]="P",Games[[#This Row],[Round]]=4),IF(Games[[#This Row],[Result]]>0.5,1,0),0) -> 0 | AL10: =IF(AND(Games[[#This Row],[Type]]="P",Games[[#This Row],[Round]]=4),IF(Games[[#This Row],[Result]]<0.5,1,0),0) -> 0
A11: 43240 | B11: 2018 | C11: =COUNTIFS(Games[Team],Games[[#This Row],[Team]],Games[Season],Games[[#This Row],[Season]],Games[Date],"<=" & Games[[#This Row],[Date]]) -> 2 | D11: R | E11: RS | F11: DAL | G11: ATL | H11: H | I11: {=IFERROR( Games[[#This Row],[Date]] - LOOKUP( 2, 1/((Games[Team]=Games[[#This Row],[Team]]) * (Games[Date] < Games[[#This Row],[Date]])), Games[Date] ) - 1, Games[[#This Row],[Date]]-$A$2)} -> 1 | J11: {=IFERROR( Games[[#This Row],[Date]] - LOOKUP( 2, 1/((Games[Opponent]=Games[[#This Row],[Opponent]]) * (Games[Date] < Games[[#This Row],[Date]])), Games[Date] ) - 1, Games[[#This Row],[Date]]-$A$2)} -> 2 | K11: =Games[[#This Row],[DaysOff]]-Games[[#This Row],[OppDaysOff]] -> -1 | L11: =Games[[#This Row],[OppDaysOff]]-Games[[#This Row],[DaysOff]] -> 1 | M11: =MAX(-16, MIN(16, Games[[#This Row],[RestDiff]]*8)) -> -8 | N11: =MAX(-16, MIN(16, Games[[#This Row],[OppRestDiff]]*8)) -> 8 | O11: {=IFERROR( LOOKUP( 2, 1/((Games[Team]=Games[[#This Row],[Team]]) * (Games[Season]=Games[[#This Row],[Season]]) * (Games[Date] < Games[[#This Row],[Date]])), Games[PostGmRate] ), IFERROR( alpha * _xlfn.XLOOKUP(Games[[#This Row],[Team]], ConfDiv[TeamID], ConfDiv[PreSeasonElo], base) + (1 - alpha) * base, base ) )} -> 1463.1619 | P11: {=IFERROR( LOOKUP( 2, 1/((Games[Team]=Games[[#This Row],[Opponent]]) * (Games[Season]=Games[[#This Row],[Season]]) * (Games[Date] < Games[[#This Row],[Date]])), Games[PostGmRate] ), IFERROR( alpha * _xlfn.XLOOKUP(Games[[#This Row],[Opponent]], ConfDiv[TeamID], ConfDiv[PreSeasonElo], base) + (1 - alpha) * base, base ) )} -> 1448.8555 | Q11: =1/(1+10^(((Games[[#This Row],[OppPreGmRate]]+IF(Games[[#This Row],[HomeAway]]="A",HCA,0)+Games[[#This Row],[OppRestAdj]])-(Games[[#This Row],[PreGmRate]]+IF(Games[[#This Row],[HomeAway]]="H",HCA,0)+Games[[#This Row],[RestAdj]]))/400)) -> 0.61628118 | R11: 101 | S11: 78 | T11: 0 | U11: =Games[[#This Row],[PointsFor]]-Games[[#This Row],[PointsAgainst]] -> 23 | V11: =IF(Games[[#This Row],[MOV]]>0,1,IF(Games[[#This Row],[MOV]]=0,0.5,0)) -> 1 | W11: =((ABS(Games[[#This Row],[MOV]])+5)^0.6)/(12+0.01*(ABS(Games[[#This Row],[PreGmRate]]-Games[[#This Row],[OppPreGmRate]])))*IF(Games[[#This Row],[OT]]=1,0.9,1) -> 0.60808818 | X11: {=IF(Games[[#This Row],[Type]]="P", _xlfn.IFS( Games[[#This Row],[Round]]=1,1.1, Games[[#This Row],[Round]]=2,1.2, Games[[#This Row],[Round]]=3,1.35, Games[[#This Row],[Round]]=4,1.5,Games[[#This Row],[Round]]=0.5,1.05, TRUE,1 ), 1)} -> 1 | Y11: =MAX(kmin, kmax - 0.15 * MIN(Games[[#This Row],[GamesPlayed]], 82)) -> 75.7 | Z11: =Games[[#This Row],[K]]*Games[[#This Row],[POMult]] -> 75.7 | AA11: =(Games[[#This Row],[Keff]]*Games[[#This Row],[MOVMult]])*(Games[[#This Row],[Result]]-Games[[#This Row],[ExpectedWin%]]) -> 17.66345 | AB11: =Games[[#This Row],[PreGmRate]]+Games[[#This Row],[RatingChange]] -> 1480.8253 | AC11: =IF(Games[[#This Row],[Type]]="R",IF(Games[[#This Row],[Result]]>0.5,1,0),0) -> 1 | AD11: =IF(Games[[#This Row],[Type]]="R",IF(Games[[#This Row],[Result]]<0.5,1,0),0) -> 0 | AE11: =IF(AND(Games[[#This Row],[Type]]="P",Games[[#This Row],[Round]]=1),IF(Games[[#This Row],[Result]]>0.5,1,0),0) -> 0 | AF11: =IF(AND(Games[[#This Row],[Type]]="P",Games[[#This Row],[Round]]=1),IF(Games[[#This Row],[Result]]<0.5,1,0),0) -> 0 | AG11: =IF(AND(Games[[#This Row],[Type]]="P",Games[[#This Row],[Round]]=2),IF(Games[[#This Row],[Result]]>0.5,1,0),0) -> 0 | AH11: =IF(AND(Games[[#This Row],[Type]]="P",Games[[#This Row],[Round]]=2),IF(Games[[#This Row],[Result]]<0.5,1,0),0) -> 0 | AI11: =IF(AND(Games[[#This Row],[Type]]="P",Games[[#This Row],[Round]]=3),IF(Games[[#This Row],[Result]]>0.5,1,0),0) -> 0 | AJ11: =IF(AND(Games[[#This Row],[Type]]="P",Games[[#This Row],[Round]]=3),IF(Games[[#This Row],[Result]]<0.5,1,0),0) -> 0 | AK11: =IF(AND(Games[[#This Row],[Type]]="P",Games[[#This Row],[Round]]=4),IF(Games[[#This Row],[Result]]>0.5,1,0),0) -> 0 | AL11: =IF(AND(Games[[#This Row],[Type]]="P",Games[[#This Row],[Round]]=4),IF(Games[[#This Row],[Result]]<0.5,1,0),0) -> 0
